Workbook

Sheet Raw Data 3Y
A1: Index Name | B1: First TRI | C1: Last TRI | D1: Years | E1: Std Dev (%) | F1: P1 Start TRI | G1: P1 End TRI | H1: P2 Start TRI | I1: P2 End TRI | J1: P3 Start TRI | K1: P3 End TRI | L1: P4 Start TRI | M1: P4 End TRI | N1: P5 Start TRI | O1: P5 End TRI | P1: P6 Start TRI | Q1: P6 End TRI | R1: P7 Start TRI | S1: P7 End TRI | T1: P8 Start TRI | U1: P8 End TRI | V1: P9 Start TRI | W1: P9 End TRI | X1: P10 Start TRI | Y1: P10 End TRI | Z1: P11 Start TRI | AA1: P11 End TRI | AB1: P12 Start TRI | AC1: P12 End TRI | AD1: P13 Start TRI | AE1: P13 End TRI | AF1: P14 Start TRI | AG1: P14 End TRI | AH1: P15 Start TRI | AI1: P15 End TRI | AJ1: P16 Start TRI | AK1: P16 End TRI | AL1: P17 Start TRI | AM1: P17 End TRI | AN1: P18 Start TRI | AO1: P18 End TRI | AP1: AMCs | AQ1: Source
A2: NIFTY 50 | B2: 2406.95 | C2: 33655.43 | D2: 20.9938 | E2: 20.83 | F2: 2406.95 | G2: 5762.88 | H2: 4028.82 | I2: 3720.51 | J2: 4379.37 | K2: 6521.55 | L2: 5769.05 | M2: 7327.83 | N2: 3769.02 | O2: 6728.46 | P2: 6573 | Q2: 7343.48 | R2: 7318.19 | S2: 8739.91 | T2: 6756.86 | U2: 11201.99 | V2: 7343.48 | W2: 10325.5 | X2: 8761.86 | Y2: 12406.69 | Z2: 11327.63 | AA2: 14000.07 | AB2: 10291.69 | AC2: 16208.94 | AD2: 12406.69 | AE2: 12105.66 | AF2: 14000.07 | AG2: 20886.52 | AH2: 16208.94 | AI2: 25118.14 | AJ2: 11621.35 | AK2: 25266.06 | AL2: 21137.69 | AM2: 33066.13 | AN2: 25413.94 | AO2: 34527.01 | AP2: Aditya Birla Sun Life Mutual Fund, Axis Mutual Fund, Bandhan Mutual Fund, Baroda BNP Paribas Mutual Fund, DSP Mutual Fund, Edelweiss Mutual Fund, Franklin Templeton Mutual Fund, HDFC Mutual Fund, HSBC Mutual Fund, ICICI Prudential Mutual Fund, Kotak Mahindra Mutual Fund, LIC Mutual Fund, Mirae Asset Mutual Fund, Motilal Oswal Mutual Fund, Navi Mutual Fund, Nippon India Mutual Fund, SBI Mutual Fund, Tata Mutual Fund, Taurus Mutual Fund, UTI Mutual Fund | AQ2: https://www.niftyindices.com/indices/equity/broad-based-indices/NIFTY--50
A3: NIFTY NEXT 50 | B3: 4957.2 | C3: 87002.31 | D3: 20.9938 | E3: 22.89 | F3: 4957.2 | G3: 9437.14 | H3: 7412.75 | I3: 5195.93 | J3: 7729.7 | K3: 13031.01 | L3: 9341.23 | M3: 13783.59 | N3: 5257.9 | O3: 12923.81 | P3: 13098.26 | Q3: 14170.03 | R3: 13883.06 | S3: 17112.8 | T3: 13028.02 | U3: 24919.87 | V3: 14170.03 | W3: 24368.02 | X3: 17056.76 | Y3: 33190.87 | Z3: 25166.74 | AA3: 39036.24 | AB3: 24374.11 | AC3: 38414.93 | AD3: 33190.87 | AE3: 28998.12 | AF3: 39036.24 | AG3: 47248.21 | AH3: 38414.93 | AI3: 57445.19 | AJ3: 28377.76 | AK3: 53231.02 | AL3: 47957.81 | AM3: 87345.98 | AN3: 58337.52 | AO3: 89043.92 | AP3: Aditya Birla Sun Life Mutual Fund, Axis Mutual Fund, DSP Mutual Fund, Edelweiss Mutual Fund, HDFC Mutual Fund, HSBC Mutual Fund, ICICI Prudential Mutual Fund, Kotak Mahindra Mutual Fund, LIC Mutual Fund, Motilal Oswal Mutual Fund, Navi Mutual Fund, SBI Mutual Fund, UTI Mutual Fund | AQ3: https://www.niftyindices.com/indices/equity/broad-based-indices/NIFTY-Next-50
A4: NIFTY SMALLCAP 50 | B4: 1000 | C4: 9332.54 | D4: 20.9938 | E4: 25.13 | F4: 1000 | G4: 2538.13 | H4: 1694.27 | I4: 1057.83 | J4: 1797.3 | K4: 2542.74 | L4: 2523.48 | M4: 2352.08 | N4: 1088.87 | O4: 2054.18 | P4: 2583.92 | Q4: 1868.02 | R4: 2398.3 | S4: 2253.8 | T4: 2075.48 | U4: 3514.44 | V4: 1868.02 | W4: 3041.78 | X4: 2257.54 | Y4: 4418.79 | Z4: 3593.45 | AA4: 4738.62 | AB4: 3089.9 | AC4: 3862.09 | AD4: 4418.79 | AE4: 2077.61 | AF4: 4738.62 | AG4: 4868.87 | AH4: 3862.09 | AI4: 5819.53 | AJ4: 2028.59 | AK4: 5015.03 | AL4: 4959.47 | AM4: 8909.44 | AN4: 5931.78 | AO4: 9505.98 | AP4: Aditya Birla Sun Life Mutual Fund, Axis Mutual Fund, Kotak Mahindra Mutual Fund | AQ4: https://www.niftyindices.com/indices/equity/broad-based-indices/niftysmallcap50
A5: NIFTY MIDCAP 150 | B5: 1000 | C5: 24753.21 | D5: 20.9938 | E5: 20.9 | F5: 1000 | G5: 2100.28 | H5: 1747.55 | I5: 1081.17 | J5: 1673.19 | K5: 2549.07 | L5: 2087.33 | M5: 2670.01 | N5: 1097.34 | O5: 2546.99 | P5: 2576.84 | Q5: 2688.28 | R5: 2706.96 | S5: 3140.17 | T5: 2571.54 | U5: 5015.68 | V5: 2688.28 | W5: 4931.69 | X5: 3134.34 | Y5: 6766.76 | Z5: 5076.14 | AA5: 8017.18 | AB5: 4956.96 | AC5: 7865.64 | AD5: 6766.76 | AE5: 5483.52 | AF5: 8017.18 | AG5: 11052.87 | AH5: 7865.64 | AI5: 13821.4 | AJ5: 5383.93 | AK5: 14203.8 | AL5: 11225.99 | AM5: 22777.89 | AN5: 13997.36 | AO5: 23964.87 | AP5: Aditya Birla Sun Life Mutual Fund, Bandhan Mutual Fund, Baroda BNP Paribas Mutual Fund, HDFC Mutual Fund, ICICI Prudential Mutual Fund, Motilal Oswal Mutual Fund, Navi Mutual Fund, Nippon India Mutual Fund, SBI Mutual Fund, UTI Mutual Fund | AQ5: https://www.niftyindices.com/indices/equity/broad-based-indices/nifty-midcap-150
A6: NIFTY50 EQUAL WEIGHT | B6: 3130.41 | C6: 50846.14 | D6: 20.9938 | E6: 20.81 | F6: 3130.41 | G6: 7585.11 | H6: 5467.38 | I6: 4742.68 | J6: 5487.03 | K6: 9653.98 | L6: 7585.04 | M6: 10429.35 | N6: 4806.96 | O6: 9954.07 | P6: 9694.48 | Q6: 10147.56 | R6: 10473.84 | S6: 12144.71 | T6: 10022.18 | U6: 15594.28 | V6: 10147.56 | W6: 14116.54 | X6: 12163.69 | Y6: 17391.88 | Z6: 15778.95 | AA6: 18792.24 | AB6: 14057.11 | AC6: 20117.03 | AD6: 17391.88 | AE6: 13717.68 | AF6: 18792.24 | AG6: 25886.34 | AH6: 20117.03 | AI6: 32000.07 | AJ6: 13264.76 | AK6: 32697.24 | AL6: 26306.38 | AM6: 47716.78 | AN6: 32391.15 | AO6: 49403.22 | AP6: Aditya Birla Sun Life Mutual Fund, DSP Mutual Fund, HDFC Mutual Fund, ICICI Prudential Mutual Fund, Kotak Mahindra Mutual Fund, SBI Mutual Fund, UTI Mutual Fund | AQ6: https://www.niftyindices.com/indices/equity/strategy-indices/nifty50-equal-weight
A7: NIFTY 100 | B7: 2158.39 | C7: 31501.34 | D7: 20.9938 | E7: 20.77 | F7: 2158.39 | G7: 5010.91 | H7: 3562.96 | I7: 3174.52 | J7: 3850.12 | K7: 5868.77 | L7: 5008.53 | M7: 6538.02 | N7: 3215.47 | O7: 6027.9 | P7: 5912.5 | Q7: 6588.79 | R7: 6537.94 | S7: 7866.04 | T7: 6057.04 | U7: 10285.91 | V7: 6588.79 | W7: 9577.13 | X7: 7879.43 | Y7: 11741.07 | Z7: 10399.2 | AA7: 13323.87 | AB7: 9550.87 | AC7: 15070.64 | AD7: 11741.07 | AE7: 11271.15 | AF7: 13323.87 | AG7: 19294.06 | AH7: 15070.64 | AI7: 23273.69 | AJ7: 10849.01 | AK7: 22905.08 | AL7: 19535.92 | AM7: 31124.63 | AN7: 23562.55 | AO7: 32302.55 | AP7: Axis Mutual Fund, Bandhan Mutual Fund, HDFC Mutual Fund | AQ7: https://www.niftyindices.com/indices/equity/broad-based-indices/nifty-100
A8: NIFTY500 VALUE 50 | B8: 1000 | C8: 25278.73 | D8: 20.9938 | E8: 25.76 | F8: 1000 | G8: 1906.04 | H8: 1373.57 | I8: 1190.74 | J8: 1365.18 | K8: 3119.05 | L8: 1903.2 | M8: 3511.15 | N8: 1213.72 | O8: 3256.21 | P8: 3137.35 | Q8: 2675.91 | R8: 3554.89 | S8: 3190.91 | T8: 3276.44 | U8: 4887.63 | V8: 2675.91 | W8: 4450.96 | X8: 3197.17 | Y8: 7190.09 | Z8: 4973.28 | AA8: 7315.78 | AB8: 4490.09 | AC8: 6753.1 | AD8: 7190.09 | AE8: 3462.04 | AF8: 7315.78 | AG8: 7228.44 | AH8: 6753.1 | AI8: 10098.45 | AJ8: 3404.89 | AK8: 11185.1 | AL8: 7426.9 | AM8: 21309.39 | AN8: 10349.92 | AO8: 22190.99 | AP8: Axis Mutual Fund, Bandhan Mutual Fund, UTI Mutual Fund | AQ8: https://www.niftyindices.com/indices/equity/strategy-indices/nifty500-value50
A9: NIFTY 500 | B9: 2250.1 | C9: 32813.14 | D9: 20.9938 | E9: 20.27 | F9: 2250.1 | G9: 4996.1 | H9: 3696.06 | I9: 3042.29 | J9: 3889.07 | K9: 5781.09 | L9: 4985.13 | M9: 6264 | N9: 3081.93 | O9: 5778.58 | P9: 5823.93 | Q9: 6186.03 | R9: 6282.41 | S9: 7327.4 | T9: 5813 | U9: 9887.5 | V9: 6186.03 | W9: 9239.92 | X9: 7338.75 | Y9: 11598.65 | Z9: 10003.76 | AA9: 13254.74 | AB9: 9230.34 | AC9: 14421.49 | AD9: 11598.65 | AE9: 10540.43 | AF9: 13254.74 | AG9: 18717.24 | AH9: 14421.49 | AI9: 22889.14 | AJ9: 10186.74 | AK9: 22609.54 | AL9: 18968.55 | AM9: 32135.55 | AN9: 23185.39 | AO9: 33361.96 | AP9: Axis Mutual Fund, ICICI Prudential Mutual Fund, Motilal Oswal Mutual Fund, SBI Mutual Fund | AQ9: https://www.niftyindices.com/indices/equity/broad-based-indices/nifty-500
A10: NIFTY MIDCAP 50 | B10: 1355.71 | C10: 19671.49 | D10: 20.9938 | E10: 25.07 | F10: 1355.71 | G10: 2533.08 | H10: 2263.82 | I10: 1265.56 | J10: 1953.89 | K10: 2963.96 | L10: 2532.6 | M10: 2788.94 | N10: 1287.56 | O10: 2599.29 | P10: 2985.95 | Q10: 2256.23 | R10: 2824.1 | S10: 2882.42 | T10: 2620.39 | U10: 3981.31 | V10: 2256.23 | W10: 3835.53 | X10: 2867.75 | Y10: 5308.47 | Z10: 4037.1 | AA10: 6193.61 | AB10: 3864.49 | AC10: 6273.01 | AD10: 5308.47 | AE10: 3974.08 | AF10: 6193.61 | AG10: 8531.23 | AH10: 6273.01 | AI10: 10440.43 | AJ10: 3867.67 | AK10: 10909.66 | AL10: 8714.17 | AM10: 17891.38 | AN10: 10599.85 | AO10: 18816.26 | AP10: Axis Mutual Fund, Kotak Mahindra Mutual Fund | AQ10: https://www.niftyindices.com/indices/equity/broad-based-indices/nifty-midcap-50
A11: NIFTY ALPHA 50 | B11: 1618.46 | C11: 54184.6 | D11: 20.9938 | E11: 24.71 | F11: 1618.46 | G11: 4261.95 | H11: 3181.88 | I11: 1880.66 | J11: 3227.58 | K11: 3744.73 | L11: 4259.06 | M11: 4032.42 | N11: 1886.79 | O11: 4282.19 | P11: 3798.63 | Q11: 4971.81 | R11: 4088.52 | S11: 5822.43 | T11: 4350.21 | U11: 10077.39 | V11: 4971.81 | W11: 9704.51 | X11: 5834.77 | Y11: 12331.86 | Z11: 10236.42 | AA11: 14908.82 | AB11: 9706.45 | AC11: 14228.49 | AD11: 12331.86 | AE11: 11814.16 | AF11: 14908.82 | AG11: 26708.8 | AH11: 14228.49 | AI11: 42099.48 | AJ11: 11707.6 | AK11: 31112.47 | AL11: 27462.71 | AM11: 58362.55 | AN11: 42731.24 | AO11: 54992.84 | AP11: Bandhan Mutual Fund | AQ11: https://www.niftyindices.com/indices/equity/strategy-indices/nifty-alpha-50
A12: NIFTY200 MOMENTUM 30 | B12: 1000 | C12: 33895.81 | D12: 20.9938 | E12: 22.41 | F12: 1000 | G12: 2651.32 | H12: 1797.03 | I12: 1725.86 | J12: 1794.92 | K12: 2811.48 | L12: 2631.9 | M12: 3206.71 | N12: 1713.11 | O12: 3198.49 | P12: 2830.48 | Q12: 3737.84 | R12: 3199.01 | S12: 4520.63 | T12: 3222.97 | U12: 7240.99 | V12: 3737.84 | W12: 6923.56 | X12: 4556.61 | Y12: 9704.96 | Z12: 7348.68 | AA12: 12050.25 | AB12: 6916.5 | AC12: 13209.56 | AD12: 9704.96 | AE12: 11002.27 | AF12: 12050.25 | AG12: 17866.29 | AH12: 13209.56 | AI12: 24607.66 | AJ12: 10616.55 | AK12: 22346.65 | AL12: 18261.82 | AM12: 38504.8 | AN12: 24772.89 | AO12: 34448.05 | AP12: Bandhan Mutual Fund, Baroda BNP Paribas Mutual Fund, HDFC Mutual Fund, ICICI Prudential Mutual Fund, Kotak Mahindra Mutual Fund, Motilal Oswal Mutual Fund, UTI Mutual Fund | AQ12: https://www.niftyindices.com/indices/equity/strategy-indices/nifty200-momentum-30-index
A13: NIFTY SMALLCAP 250 | B13: 1000 | C13: 18183.31 | D13: 20.9938 | E13: 21.56 | F13: 1000 | G13: 2624.3 | H13: 1786.61 | I13: 1183.49 | J13: 1941.41 | K13: 2857.15 | L13: 2607.61 | M13: 2883.17 | N13: 1214.02 | O13: 2635.24 | P13: 2904.77 | Q13: 2543.15 | R13: 2938.16 | S13: 3068.39 | T13: 2668.78 | U13: 4994.23 | V13: 2543.15 | W13: 4697.09 | X13: 3075.14 | Y13: 6602.37 | Z13: 5105.06 | AA13: 7598.12 | AB13: 4742.59 | AC13: 6586.72 | AD13: 6602.37 | AE13: 3900.5 | AF13: 7598.12 | AG13: 8529.76 | AH13: 6586.72 | AI13: 11687.4 | AJ13: 3862.36 | AK13: 10982.49 | AL13: 8697.4 | AM13: 18570.61 | AN13: 11908.62 | AO13: 19018.8 | AP13: Bandhan Mutual Fund, Edelweiss Mutual Fund, Groww Mutual Fund, HDFC Mutual Fund, ICICI Prudential Mutual Fund, Kotak Mahindra Mutual Fund, Motilal Oswal Mutual Fund, Nippon India Mutual Fund, SBI Mutual Fund | AQ13: https://www.niftyindices.com/indices/equity/broad-based-indices/niftysmallcap250
... A18: NIFTY SMALLCAP250 QUALITY 50 | B18: 1000 | C18: 31098.58 | D18: 20.9938 | E18: 19.59 | F18: 1000 | G18: 1833.33 | H18: 1633.21 | I18: 932.23 | J18: 1573.37 | K18: 2587.5 | L18: 1832 | M18: 2990.59 | N18: 950.45 | O18: 2903.32 | P18: 2618.87 | Q18: 3096.25 | R18: 3037.06 | S18: 4172.32 | T18: 2938.34 | U18: 6947.29 | V18: 3096.25 | W18: 7003.31 | X18: 4174.5 | Y18: 10080.93 | Z18: 7130.57 | AA18: 11413.18 | AB18: 7035.66 | AC18: 10746.59 | AD18: 10080.93 | AE18: 7005.64 | AF18: 11413.18 | AG18: 14640.91 | AH18: 10746.59 | AI18: 20499.52 | AJ18: 6928.01 | AK18: 20714.27 | AL18: 14885.53 | AM18: 33248.75 | AN18: 20872.27 | AO18: 34004.51 | AP18: DSP Mutual Fund | AQ18: https://www.niftyindices.com/indices/equity/strategy-indices/nifty-smallcap250-quality50
A19: NIFTY TOP 10 EQUAL WEIGHT | B19: 1000 | C19: 10814.47 | D19: 20.0767 | E19: 22.14 | G19: 1420.97 | H19: 1074.62 | I19: 930.67 | J19: 1261.57 | K19: 1675.64 | L19: 1425.48 | M19: 1981.65 | N19: 952.41 | O19: 1859.56 | P19: 1685.52 | Q19: 2219.63 | R19: 1973.71 | S19: 2653.89 | T19: 1873.79 | U19: 3305.98 | V19: 2219.63 | W19: 3025.51 | X19: 2660.1 | Y19: 3711.35 | Z19: 3336.22 | AA19: 4292.79 | AB19: 3032.14 | AC19: 5625.16 | AD19: 3711.35 | AE19: 4394.52 | AF19: 4292.79 | AG19: 7380.33 | AH19: 5625.16 | AI19: 8440.96 | AJ19: 4181.24 | AK19: 9302.95 | AL19: 7445.51 | AM19: 11111.96 | AN19: 8542.49 | AO19: 11960.92 | AP19: DSP Mutual Fund | AQ19: https://www.niftyindices.com/indices/equity/strategy-indices/nifty-top-10-equal-weight
A20: NIFTY MIDCAP150 QUALITY 50 | B20: 1000 | C20: 28092.86 | D20: 20.9938 | E20: 17.75 | F20: 1000 | G20: 1941.32 | H20: 1760.02 | I20: 1262.77 | J20: 1710.5 | K20: 3094.12 | L20: 1926.24 | M20: 3722.34 | N20: 1266.12 | O20: 3726.12 | P20: 3109.02 | Q20: 3825.87 | R20: 3751.25 | S20: 4919.86 | T20: 3745.33 | U20: 8030.2 | V20: 3825.87 | W20: 7710.41 | X20: 4905.63 | Y20: 10447.8 | Z20: 8120.08 | AA20: 13179.29 | AB20: 7733.41 | AC20: 13023.02 | AD20: 10447.8 | AE20: 10297.42 | AF20: 13179.29 | AG20: 18346.01 | AH20: 13023.02 | AI20: 21809.69 | AJ20: 10147.02 | AK20: 20153.74 | AL20: 18398.74 | AM20: 27395.04 | AN20: 21880.75 | AO20: 29093.83 | AP20: DSP Mutual Fund, UTI Mutual Fund | AQ20: https://www.niftyindices.com/indices/equity/strategy-indices/nifty-midcap150-quality-50
A21: NIFTY500 MULTICAP MOMENTUM QUALITY 50 | B21: 1000 | C21: 47199.55 | D21: 20.9938 | E21: 19.1 | F21: 1000 | G21: 2278.5 | H21: 2012.49 | I21: 1538.73 | J21: 1918 | K21: 3142.57 | L21: 2244.86 | M21: 3625.89 | N21: 1538.93 | O21: 3801.21 | P21: 3177.66 | Q21: 4397.7 | R21: 3646.34 | S21: 5915.46 | T21: 3830.16 | U21: 10159.32 | V21: 4397.7 | W21: 9651.8 | X21: 5960.07 | Y21: 12177.93 | Z21: 10315.27 | AA21: 14895.01 | AB21: 9675.65 | AC21: 16143.7 | AD21: 12177.93 | AE21: 14136.22 | AF21: 14895.01 | AG21: 23208.07 | AH21: 16143.7 | AI21: 32876.07 | AJ21: 13846.06 | AK21: 29491.43 | AL21: 23457.96 | AM21: 51826.54 | AN21: 33120.62 | AO21: 48365.9 | AP21: Edelweiss Mutual Fund | AQ21: https://www.niftyindices.com/indices/equity/strategy-indices/nifty500-multicap-momentum-quality50
A22: NIFTY LARGEMIDCAP 250 | B22: 1000 | C22: 18939.96 | D22: 20.9938 | E22: 20.12 | F22: 1000 | G22: 2198.09 | H22: 1689.24 | I22: 1256 | J22: 1713.68 | K22: 2607.64 | L22: 2191.38 | M22: 2792.41 | N22: 1273.24 | O22: 2616.22 | P22: 2630.06 | Q22: 2806.42 | R22: 2811.16 | S22: 3328.28 | T22: 2635.13 | U22: 4819.92 | V22: 2806.42 | W22: 4613.85 | X22: 3328.18 | Y22: 5991.47 | Z22: 4875.68 | AA22: 6958.58 | AB22: 4619.35 | AC22: 7334.14 | AD22: 5991.47 | AE22: 5301.41 | AF22: 6958.58 | AG22: 9855.64 | AH22: 7334.14 | AI22: 12112.92 | AJ22: 5152.25 | AK22: 12188.35 | AL22: 9994.66 | AM22: 18024.27 | AN22: 12265.2 | AO22: 18865.51 | AP22: Edelweiss Mutual Fund, HDFC Mutual Fund, ICICI Prudential Mutual Fund, Mirae Asset Mutual Fund, Zerodha Mutual Fund | AQ22: https://www.niftyindices.com/indices/equity/broad-based-indices/nifty-largemidcap-250
A23: NIFTY MIDCAP150 MOMENTUM 50 | B23: 1000 | C23: 66945.19 | D23: 20.9938 | E23: 21.2 | F23: 1000 | G23: 2531.75 | H23: 2067.55 | I23: 1342.66 | J23: 1935.4 | K23: 2867.8 | L23: 2491.56 | M23: 3387.39 | N23: 1346.91 | O23: 3589.03 | P23: 2902.66 | Q23: 4444.82 | R23: 3407.43 | S23: 5425.27 | T23: 3621.17 | U23: 9971.12 | V23: 4444.82 | W23: 10085.49 | X23: 5432.83 | Y23: 13952.44 | Z23: 10096.96 | AA23: 17879.19 | AB23: 10111.65 | AC23: 16855.16 | AD23: 13952.44 | AE23: 13619.34 | AF23: 17879.19 | AG23: 27265.07 | AH23: 16855.16 | AI23: 38336.35 | AJ23: 13377.69 | AK23: 37811.02 | AL23: 27902.07 | AM23: 66030.98 | AN23: 38516.85 | AO23: 66875.18 | AP23: Edelweiss Mutual Fund, Kotak Mahindra Mutual Fund, Tata Mutual Fund | AQ23: https://www.niftyindices.com/indices/equity/strategy-indices/nifty-midcap150-momentum-50
A24: NIFTY500 MULTICAP 50:25:25 | B24: 1000 | C24: 18552.25 | D24: 20.9938 | E24: 19.89 | F24: 1000 | G24: 2246.28 | H24: 1668.79 | I24: 1299.26 | J24: 1758.21 | K24: 2754.13 | L24: 2241.34 | M24: 2977.24 | N24: 1319.69 | O24: 2791.53 | P24: 2781.65 | Q24: 2902.93 | R24: 3004.01 | S24: 3482.21 | T24: 2814.27 | U24: 5050.68 | V24: 2902.93 | W24: 4792.72 | X24: 3489.3 | Y24: 6256.93 | Z24: 5122.71 | AA24: 7215.43 | AB24: 4803.9 | AC24: 7381.43 | AD24: 6256.93 | AE24: 5130.27 | AF24: 7215.43 | AG24: 9741.41 | AH24: 7381.43 | AI24: 12260.19 | AJ24: 4995.35 | AK24: 12068.74 | AL24: 9888.57 | AM24: 18095.5 | AN24: 12433.53 | AO24: 18828.78 | AP24: HDFC Mutual Fund, Navi Mutual Fund | AQ24: https://www.niftyindices.com/indices/equity/broad-based-indices/nifty500-multicap-50-25-25-index
A25: NIFTY100 EQUAL WEIGHT | B25: 2652.85 | C25: 42556.49 | D25: 20.9938 | E25: 20.87 | F25: 2652.85 | G25: 5352.2 | H25: 4162.98 | I25: 3251.4 | J25: 4211.31 | K25: 7517.76 | L25: 5343.71 | M25: 8050.05 | N25: 3299.3 | O25: 7660.31 | P25: 7560.28 | Q25: 7946.36 | R25: 8111.9 | S25: 9642.78 | T25: 7715.51 | U25: 13105.8 | V25: 7946.36 | W25: 12364.77 | X25: 9633.27 | Y25: 15911.33 | Z25: 13256.96 | AA25: 17717.62 | AB25: 12348.57 | AC25: 17983.98 | AD25: 15911.33 | AE25: 12717.64 | AF25: 17717.62 | AG25: 22914.62 | AH25: 17983.98 | AI25: 27871.61 | AJ25: 12375.24 | AK25: 26780.81 | AL25: 23264.1 | AM25: 41530.28 | AN25: 28292.61 | AO25: 42490.88 | AP25: HDFC Mutual Fund, Sundaram Mutual Fund | AQ25: https://www.niftyindices.com/indices/equity/strategy-indices/nifty-100-equal-weight
A26: NIFTY200 VALUE 30 | B26: 1000 | C26: 24584.63 | D26: 20.9938 | E26: 26.2 | F26: 1000 | G26: 1873.05 | H26: 1433.12 | I26: 1214.11 | J26: 1247.62 | K26: 3191.27 | L26: 1874.13 | M26: 3903.87 | N26: 1230.97 | O26: 3820.84 | P26: 3217.98 | Q26: 3358.03 | R26: 3940.64 | S26: 3978.92 | T26: 3846.17 | U26: 4976.36 | V26: 3358.03 | W26: 4172.34 | X26: 3936.73 | Y26: 6579.8 | Z26: 5070.23 | AA26: 6725.58 | AB26: 4206.55 | AC26: 6349.87 | AD26: 6579.8 | AE26: 3451.93 | AF26: 6725.58 | AG26: 6808.67 | AH26: 6349.87 | AI26: 9119.14 | AJ26: 3370.45 | AK26: 10485.07 | AL26: 7018.04 | AM26: 20043.08 | AN26: 9319.36 | AO26: 21329.93 | AP26: ICICI Prudential Mutual Fund | AQ26: https://www.niftyindices.com/indices/equity/strategy-indices/nifty200-value30
A27: NIFTY50 VALUE 20 | B27: 1000 | C27: 16201.69 | D27: 17.2402 | E27: 17.86 | I27: 1032.94 | K27: 2176.38 | M27: 2639.76 | N27: 1049.72 | O27: 2491.47 | P27: 2191.97 | Q27: 2789.34 | R27: 2632.59 | S27: 3374.93 | T27: 2497.8 | U27: 4172.98 | V27: 2789.34 | W27: 4061.24 | X27: 3388.3 | Y27: 4638.15 | Z27: 4193.17 | AA27: 5334.82 | AB27: 4034.03 | AC27: 6760.94 | AD27: 4638.15 | AE27: 5449.69 | AF27: 5334.82 | AG27: 9418.82 | AH27: 6760.94 | AI27: 11806.22 | AJ27: 5209.95 | AK27: 12163.47 | AL27: 9526.87 | AM27: 16531.21 | AN27: 11921.54 | AO27: 16976.27 | AP27: ICICI Prudential Mutual Fund, Nippon India Mutual Fund | AQ27: https://www.niftyindices.com/indices/equity/strategy-indices/nifty-50-value-20
A28: NIFTY500 EQUAL WEIGHT | B28: 1000 | C28: 15957.8 | D28: 20.9938 | E28: 20.73 | F28: 1000 | G28: 1955.05 | H28: 1657.85 | I28: 1068.79 | J28: 1602.64 | K28: 2703 | L28: 1955.62 | M28: 2852.42 | N28: 1091.88 | O28: 2635.85 | P28: 2744.24 | Q28: 2497.69 | R28: 2903.75 | S28: 2945.09 | T28: 2673.57 | U28: 4482.78 | V28: 2497.69 | W28: 4277.71 | X28: 2960.14 | Y28: 5819.95 | Z28: 4566.12 | AA28: 6610.52 | AB28: 4312.33 | AC28: 5973.33 | AD28: 5819.95 | AE28: 3691.95 | AF28: 6610.52 | AG28: 7699.59 | AH28: 5973.33 | AI28: 9933.72 | AJ28: 3651.39 | AK28: 9726.96 | AL28: 7846.02 | AM28: 15945.83 | AN28: 10123.81 | AO28: 16361.1 | AP28: Nippon India Mutual Fund | AQ28: https://www.niftyindices.com/indices/equity/strategy-indices/nifty500--equal--weight
A29: NIFTY200 ALPHA 30 | B29: 1000 | C29: 27721.36 | D29: 20.9938 | E29: 24.31 | F29: 1000 | G29: 2423.26 | H29: 1816.25 | I29: 1212.74 | J29: 1777.31 | K29: 2100.07 | L29: 2414.48 | M29: 2238.42 | N29: 1206.62 | O29: 2243.92 | P29: 2115.18 | Q29: 2527.61 | R29: 2239.44 | S29: 3118.95 | T29: 2266.39 | U29: 4914.92 | V29: 2527.61 | W29: 4880.29 | X29: 3150.25 | Y29: 6883.09 | Z29: 4973.72 | AA29: 8464.82 | AB29: 4875.52 | AC29: 8889.21 | AD29: 6883.09 | AE29: 7340.76 | AF29: 8464.82 | AG29: 12094.47 | AH29: 8889.21 | AI29: 17220.91 | AJ29: 7064.86 | AK29: 15598.42 | AL29: 12346.65 | AM29: 29342.68 | AN29: 17333.98 | AO29: 27607.92 | AP29: Tata Mutual Fund | AQ29: https://www.niftyindices.com/indices/equity/strategy-indices/nifty200-alpha-30
A30: NIFTY 200 | B30: 1171.5 | C30: 16699.39 | D30: 20.9938 | E30: 20.54 | F30: 1171.5 | G30: 2628.75 | H30: 1917.98 | I30: 1615.6 | J30: 2033.35 | K30: 3010.95 | L30: 2626.74 | M30: 3297.63 | N30: 1636.23 | O30: 3038.29 | P30: 3031.22 | Q30: 3286.19 | R30: 3302.61 | S30: 3900.02 | T30: 3054.35 | U30: 5192.52 | V30: 3286.19 | W30: 4832.98 | X30: 3905.37 | Y30: 5992.56 | Z30: 5251.48 | AA30: 6818.58 | AB30: 4823.14 | AC30: 7568.22 | AD30: 5992.56 | AE30: 5572.96 | AF30: 6818.58 | AG30: 9730.71 | AH30: 7568.22 | AI30: 11810.19 | AJ30: 5374.22 | AK30: 11681.18 | AL30: 9859.13 | AM30: 16304.76 | AN30: 11960.76 | AO30: 16951.35 | AQ30: https://www.niftyindices.com/indices/equity/broad-based-indices/nifty-200
A31: NIFTY MIDCAP 100 | B31: 3178.35 | C31: 71569.29 | D31: 20.9938 | E31: 21.3 | F31: 3178.35 | G31: 6933.16 | H31: 5175.1 | I31: 3850.83 | J31: 5156.98 | K31: 8834.32 | L31: 6896.34 | M31: 9321.95 | N31: 3878.35 | O31: 9075.07 | P31: 8913.65 | Q31: 8948.16 | R31: 9425.12 | S31: 10467.99 | T31: 9140.67 | U31: 15965.18 | V31: 8948.16 | W31: 15873.06 | X31: 10437.44 | Y31: 21660.5 | Z31: 16152.34 | AA31: 24314.28 | AB31: 15922.06 | AC31: 23532.57 | AD31: 21660.5 | AE31: 15219.69 | AF31: 24314.28 | AG31: 31034.74 | AH31: 23532.57 | AI31: 39306.45 | AJ31: 14916.92 | AK31: 40096.64 | AL31: 31590.85 | AM31: 65746.94 | AN31: 39891.93 | AO31: 69200.61 | AQ31: https://www.niftyindices.com/indices/equity/broad-based-indices/NIFTY-Midcap-100
A32: NIFTY MIDSMALLCAP 400 | B32: 1000 | C32: 22315.09 | D32: 20.9938 | E32: 20.88 | F32: 1000 | G32: 2257.61 | H32: 1759.14 | I32: 1112.49 | J32: 1754.2 | K32: 2642.98 | L32: 2243.53 | M32: 2735.11 | N32: 1132.96 | O32: 2571 | P32: 2676.64 | Q32: 2636.07 | R32: 2777.62 | S32: 3111.03 | T32: 2598.41 | U32: 5002.13 | V32: 2636.07 | W32: 4847.78 | X32: 3109.23 | Y32: 6706.21 | Z32: 5078.93 | AA32: 7865.86 | AB32: 4879.7 | AC32: 7415.06 | AD32: 6706.21 | AE32: 4912.29 | AF32: 7865.86 | AG32: 10149.29 | AH32: 7415.06 | AI32: 13050.34 | AJ32: 4835.08 | AK32: 13041.87 | AL32: 10320.18 | AM32: 21297.05 | AN32: 13242.18 | AO32: 22191.58 | AQ32: https://www.niftyindices.com/indices/equity/broad-based-indices/nifty-midsmallcap-400
A33: NIFTY SMALLCAP 100 | B33: 1501.99 | C33: 19675.32 | D33: 20.9938 | E33: 25.43 | F33: 1501.99 | G33: 3997.33 | H33: 2704.36 | I33: 1698.66 | J33: 3066.09 | K33: 3954.92 | L33: 3965.29 | M33: 3958.88 | N33: 1732.44 | O33: 3786.61 | P33: 3998.11 | Q33: 3626.58 | R33: 4032.14 | S33: 4247.93 | T33: 3853.52 | U33: 6524.85 | V33: 3626.58 | W33: 5732.33 | X33: 4263.61 | Y33: 8261.21 | Z33: 6632.77 | AA33: 9547.94 | AB33: 5849.37 | AC33: 8193.7 | AD33: 8261.21 | AE33: 4438.25 | AF33: 9547.94 | AG33: 10094.65 | AH33: 8193.7 | AI33: 13105.79 | AJ33: 4371.44 | AK33: 11409.49 | AL33: 10305.42 | AM33: 20130.98 | AN33: 13325.6 | AO33: 20550.77 | AQ33: https://www.niftyindices.com/indices/equity/broad-based-indices/NIFTY-Smallcap-100
A34: NIFTY500 LARGEMIDSMALL EQUAL-CAP WEIGHTED | B34: 1000 | C34: 20286.53 | D34: 20.9938 | E34: 20.02 | F34: 1000 | G34: 2238.9 | H34: 1682.12 | I34: 1261.41 | J34: 1762.16 | K34: 2807.86 | L34: 2233.84 | M34: 3030.9 | N34: 1282.69 | O34: 2854.86 | P34: 2839.54 | Q34: 2921.42 | R34: 3067.35 | S34: 3507.61 | T34: 2880.95 | U34: 5255.02 | V34: 2921.42 | W34: 5013.97 | X34: 3514.71 | Y34: 6678.87 | Z34: 5335.96 | AA34: 7742.59 | AB34: 5033.48 | AC34: 7651.33 | AD34: 6678.87 | AE34: 5181.01 | AF34: 7742.59 | AG34: 10146.08 | AH34: 7651.33 | AI34: 12957.61 | AJ34: 5065.07 | AK34: 12749.12 | AL34: 10307.56 | AM34: 19726.73 | AN34: 13147.53 | AO34: 20523.48 | AQ34: https://www.niftyindices.com/indices/equity/broad-based-indices/nifty500-large-midsmall-equal-cap-weighted
A35: NIFTY ALPHA QUALITY LOW-VOLATILITY 30 | B35: 1000 | C35: 27525.99 | D35: 20.9938 | E35: 16.8 | F35: 1000 | G35: 2123.69 | H35: 1756.92 | I35: 1579.04 | J35: 1817.92 | K35: 2807.13 | L35: 2102.93 | M35: 3250.98 | N35: 1572.89 | O35: 3529.02 | P35: 2811.72 | Q35: 4100.73 | R35: 3258.11 | S35: 5059.56 | T35: 3543.08 | U35: 7563.44 | V35: 4100.73 | W35: 7321.01 | X35: 5075.62 | Y35: 9287.58 | Z35: 7619.75 | AA35: 10811.16 | AB35: 7313.36 | AC35: 11772.32 | AD35: 9287.58 | AE35: 10015.24 | AF35: 10811.16 | AG35: 15316.3 | AH35: 11772.32 | AI35: 18213.98 | AJ35: 9660.22 | AK35: 17959.16 | AL35: 15386.13 | AM35: 28018.85 | AN35: 18281.59 | AO35: 27522.17 | AQ35: https://www.niftyindices.com/indices/equity/strategy-indices/nifty-alpha-quality-low-volatility30
A36: NIFTY ALPHA QUALITY VALUE LOW-VOLATILITY 30 | B36: 1000 | C36: 27809.15 | D36: 20.9938 | E36: 17.06 | F36: 1000 | G36: 1869.13 | H36: 1593.72 | I36: 1392.44 | J36: 1563.73 | K36: 2644.49 | L36: 1875.73 | M36: 3098.16 | N36: 1388.64 | O36: 3228.59 | P36: 2649.09 | Q36: 3657.05 | R36: 3100.24 | S36: 4424.93 | T36: 3232.79 | U36: 6264.84 | V36: 3657.05 | W36: 6162.77 | X36: 4441.97 | Y36: 7764.42 | Z36: 6306.07 | AA36: 9043.03 | AB36: 6145.73 | AC36: 9725.62 | AD36: 7764.42 | AE36: 8172.46 | AF36: 9043.03 | AG36: 12599.52 | AH36: 9725.62 | AI36: 15061.57 | AJ36: 7891.17 | AK36: 16333.72 | AL36: 12671.47 | AM36: 26933.88 | AN36: 15176.92 | AO36: 27913.52 | AQ36: https://www.niftyindices.com/indices/equity/strategy-indices/nifty-alpha-quality-value-low-volatility30
A37: NIFTY HIGH BETA 50 | B37: 1277.44 | C37: 4275.19 | D37: 20.9938 | E37: 32.25 | F37: 1277.44 | G37: 2359.41 | H37: 1864.63 | I37: 1100.46 | J37: 1798 | K37: 2690.56 | L37: 2356.04 | M37: 2349.37 | N37: 1142.94 | O37: 1826.11 | P37: 2720.88 | Q37: 1458.17 | R37: 2415.41 | S37: 1610.22 | T37: 1856.77 | U37: 2029.35 | V37: 1458.17 | W37: 1585.6 | X37: 1601.44 | Y37: 2206.92 | Z37: 2070.5 | AA37: 2427.49 | AB37: 1617.58 | AC37: 2132.39 | AD37: 2206.92 | AE37: 915.55 | AF37: 2427.49 | AG37: 2163.56 | AH37: 2132.39 | AI37: 2633.95 | AJ37: 893.5 | AK37: 2586.46 | AL37: 2228.4 | AM37: 4760.47 | AN37: 2705.93 | AO37: 4242.2 | AQ37: https://www.niftyindices.com/indices/equity/strategy-indices/nifty-high-beta50
A38: NIFTY LOW VOLATILITY 50 | B38: 1233.5 | C38: 31340.61 | D38: 20.9938 | E38: 16.23 | F38: 1233.5 | G38: 2813.62 | H38: 2297.29 | I38: 2063.85 | J38: 2262.88 | K38: 3968.47 | L38: 2817.73 | M38: 4664.81 | N38: 2062.1 | O38: 4603.01 | P38: 3972.45 | Q38: 5118.25 | R38: 4672.02 | S38: 5932.62 | T38: 4611.54 | U38: 8718.5 | V38: 5118.25 | W38: 8748.33 | X38: 5929.2 | Y38: 10716.19 | Z38: 8803.52 | AA38: 12117.31 | AB38: 8723.9 | AC38: 12985.97 | AD38: 10716.19 | AE38: 11191.8 | AF38: 12117.31 | AG38: 17835.11 | AH38: 12985.97 | AI38: 20233.2 | AJ38: 10887.07 | AK38: 20953.08 | AL38: 17947.67 | AM38: 30047.5 | AN38: 20471.99 | AO38: 31990.86 | AQ38: https://www.niftyindices.com/indices/equity/strategy-indices/nifty-low-volatility50
A39: NIFTY MIDSMALLCAP400 MOMENTUM QUALITY 100 | B39: 1000 | C39: 55527.25 | D39: 20.9938 | E39: 20.15 | F39: 1000 | G39: 2951.78 | H39: 2101.41 | I39: 1652.74 | J39: 2316.56 | K39: 3752.26 | L39: 2919.14 | M39: 4351.94 | N39: 1663.52 | O39: 4334.54 | P39: 3788.26 | Q39: 5049.36 | R39: 4399.39 | S39: 6504.42 | T39: 4368.92 | U39: 11469.28 | V39: 5049.36 | W39: 11083.26 | X39: 6516.31 | Y39: 14981 | Z39: 11657.5 | AA39: 18639.77 | AB39: 11119.1 | AC39: 18202.34 | AD39: 14981 | AE39: 13851.43 | AF39: 18639.77 | AG39: 26256.6 | AH39: 18202.34 | AI39: 36041.35 | AJ39: 13607.34 | AK39: 34620.28 | AL39: 26523 | AM39: 56805.59 | AN39: 36276.94 | AO39: 56155.64 | AQ39: https://www.niftyindices.com/indices/equity/strategy-indices/nifty-midsmallcap400-momentum-quality-100
A40: NIFTY QUALITY LOW-VOLATILITY 30 | B40: 1000 | C40: 21005.81 | D40: 20.9938 | E40: 16.07 | F40: 1000 | G40: 2035.66 | H40: 1767.36 | I40: 1568.36 | J40: 1800.83 | K40: 2780 | L40: 2034.06 | M40: 3258.42 | N40: 1560.94 | O40: 3627.5 | P40: 2779.82 | Q40: 4148.86 | R40: 3277.48 | S40: 5237.55 | T40: 3639.61 | U40: 7686.2 | V40: 4148.86 | W40: 7553.13 | X40: 5242.92 | Y40: 8608.01 | Z40: 7726.69 | AA40: 9759.8 | AB40: 7540.27 | AC40: 10471.97 | AD40: 8608.01 | AE40: 8928.96 | AF40: 9759.8 | AG40: 13620.27 | AH40: 10471.97 | AI40: 15834.85 | AJ40: 8647.1 | AK40: 16081.84 | AL40: 13662.74 | AM40: 22071.59 | AN40: 15955.82 | AO40: 21990.37 | AQ40: https://www.niftyindices.com/indices/equity/strategy-indices/nifty-quality-low-volatility30
A41: NIFTY SMALLCAP250 MOMENTUM QUALITY 100 | B41: 1000 | C41: 50402.11 | D41: 20.9938 | E41: 21.72 | F41: 1000 | G41: 2906.69 | H41: 1999.67 | I41: 1492.32 | J41: 2395.42 | K41: 3783.79 | L41: 2906.13 | M41: 4155.66 | N41: 1535.19 | O41: 4175.04 | P41: 3836.36 | Q41: 4631.83 | R41: 4225.3 | S41: 6237.37 | T41: 4216.7 | U41: 11076.81 | V41: 4631.83 | W41: 10785.46 | X41: 6249.18 | Y41: 15830.15 | Z41: 11380.05 | AA41: 19684.96 | AB41: 10861.68 | AC41: 18643.74 | AD41: 15830.15 | AE41: 12209.26 | AF41: 19684.96 | AG41: 26419.46 | AH41: 18643.74 | AI41: 37438.34 | AJ41: 12018.16 | AK41: 34948.49 | AL41: 26866.77 | AM41: 58278.19 | AN41: 38085.17 | AO41: 55452.52 | AQ41: https://www.niftyindices.com/indices/equity/strategy-indices/nifty-smallcap250-momentum-quality-100
A42: NIFTY TOP 15 EQUAL WEIGHT | B42: 1000 | C42: 11864 | D42: 20.0767 | E42: 21.94 | G42: 1651.23 | H42: 1081.11 | I42: 1103.98 | J42: 1242.61 | K42: 2038.76 | L42: 1634.31 | M42: 2360.79 | N42: 1126.12 | O42: 2175.44 | P42: 2054.3 | Q42: 2425.91 | R42: 2354.88 | S42: 2993.05 | T42: 2193.88 | U42: 3942.11 | V42: 2425.91 | W42: 3581.06 | X42: 3002.26 | Y42: 4229.04 | Z42: 3989.77 | AA42: 4728.23 | AB42: 3576.79 | AC42: 5706.12 | AD42: 4229.04 | AE42: 4098.77 | AF42: 4728.23 | AG42: 7082.28 | AH42: 5706.12 | AI42: 8455.56 | AJ42: 3909.95 | AK42: 9105.98 | AL42: 7161.72 | AM42: 11493.94 | AN42: 8574.48 | AO42: 12317.4 | AQ42: https://www.niftyindices.com/indices/equity/strategy-indices/nifty-top15-equal-weight
A43: NIFTY TOP 20 EQUAL WEIGHT | B43: 1000 | C43: 10737.43 | D43: 20.0767 | E43: 21.54 | G43: 1576.25 | H43: 1074.7 | I43: 1038.21 | J43: 1177.79 | K43: 1927.02 | L43: 1565.19 | M43: 2229.89 | N43: 1053.98 | O43: 2059.91 | P43: 1936.77 | Q43: 2193.49 | R43: 2224.46 | S43: 2639.04 | T43: 2071.51 | U43: 3475.21 | V43: 2193.49 | W43: 3126.74 | X43: 2645.19 | Y43: 3738.19 | Z43: 3527.7 | AA43: 4235.31 | AB43: 3112.08 | AC43: 4812.26 | AD43: 3738.19 | AE43: 3581.26 | AF43: 4235.31 | AG43: 6329.22 | AH43: 4812.26 | AI43: 7412.45 | AJ43: 3425.06 | AK43: 7956.08 | AL43: 6406.94 | AM43: 10552.22 | AN43: 7511.39 | AO43: 11133.89 | AQ43: https://www.niftyindices.com/indices/equity/strategy-indices/nifty-top20-equal-weight
A44: NIFTY100 ALPHA 30 | B44: 1000 | C44: 20211.59 | D44: 20.9938 | E44: 22.11 | F44: 1000 | G44: 2607.38 | H44: 1767.4 | I44: 1308.27 | J44: 1960.1 | K44: 2160.82 | L44: 2599.04 | M44: 2516.82 | N44: 1305.46 | O44: 2518.61 | P44: 2178.44 | Q44: 2939.2 | R44: 2515.68 | S44: 3364 | T44: 2536.95 | U44: 4961.73 | V44: 2939.2 | W44: 4809.67 | X44: 3384.05 | Y44: 6519.46 | Z44: 5024.59 | AA44: 7641.13 | AB44: 4797.17 | AC44: 8547.91 | AD44: 6519.46 | AE44: 7502.03 | AF44: 7641.13 | AG44: 11504.39 | AH44: 8547.91 | AI44: 16054.19 | AJ44: 7225.57 | AK44: 12756.21 | AL44: 11821.78 | AM44: 22332.21 | AN44: 16141.97 | AO44: 20897.12 | AQ44: https://www.niftyindices.com/indices/equity/strategy-indices/nifty100-alpha30
...

Sheet Analysis 3Y
A1: Index Name | B1: CAGR (%) | C1: Std Dev (%) | D1: Years of Data | E1: Average 3 Year Rolling Return (%) | F1: Year 1 | G1: Year 2 | H1: Year 3 | I1: Year 4 | J1: Year 5 | K1: Year 6 | L1: Year 7 | M1: Year 8 | N1: Year 9 | O1: Year 10 | P1: Year 11 | Q1: Year 12 | R1: Year 13 | S1: Year 14 | T1: Year 15 | U1: Year 16 | V1: Year 17 | W1: Year 18 | X1: Top Quartile Count | Y1: Bottom Quartile Count | Z1: Top/Bottom | AA1: AMCs | AB1: Source
A2: ='Raw Data 3Y'!A41 | B2: =IFERROR((('Raw Data 3Y'!C41/'Raw Data 3Y'!B41)^(1/'Raw Data 3Y'!D41)-1)*100,"") | C2: ='Raw Data 3Y'!E41 | D2: =INT('Raw Data 3Y'!D41) | E2: =IFERROR(AVERAGE(F2:W2),"") | F2: =IFERROR((('Raw Data 3Y'!G41/'Raw Data 3Y'!F41)^(1/3)-1)*100,"") | G2: =IFERROR((('Raw Data 3Y'!I41/'Raw Data 3Y'!H41)^(1/3)-1)*100,"") | H2: =IFERROR((('Raw Data 3Y'!K41/'Raw Data 3Y'!J41)^(1/3)-1)*100,"") | I2: =IFERROR((('Raw Data 3Y'!M41/'Raw Data 3Y'!L41)^(1/3)-1)*100,"") | J2: =IFERROR((('Raw Data 3Y'!O41/'Raw Data 3Y'!N41)^(1/3)-1)*100,"") | K2: =IFERROR((('Raw Data 3Y'!Q41/'Raw Data 3Y'!P41)^(1/3)-1)*100,"") | L2: =IFERROR((('Raw Data 3Y'!S41/'Raw Data 3Y'!R41)^(1/3)-1)*100,"") | M2: =IFERROR((('Raw Data 3Y'!U41/'Raw Data 3Y'!T41)^(1/3)-1)*100,"") | N2: =IFERROR((('Raw Data 3Y'!W41/'Raw Data 3Y'!V41)^(1/3)-1)*100,"") | O2: =IFERROR((('Raw Data 3Y'!Y41/'Raw Data 3Y'!X41)^(1/3)-1)*100,"") | P2: =IFERROR((('Raw Data 3Y'!AA41/'Raw Data 3Y'!Z41)^(1/3)-1)*100,"") | Q2: =IFERROR((('Raw Data 3Y'!AC41/'Raw Data 3Y'!AB41)^(1/3)-1)*100,"") | R2: =IFERROR((('Raw Data 3Y'!AE41/'Raw Data 3Y'!AD41)^(1/3)-1)*100,"") | S2: =IFERROR((('Raw Data 3Y'!AG41/'Raw Data 3Y'!AF41)^(1/3)-1)*100,"") | T2: =IFERROR((('Raw Data 3Y'!AI41/'Raw Data 3Y'!AH41)^(1/3)-1)*100,"") | U2: =IFERROR((('Raw Data 3Y'!AK41/'Raw Data 3Y'!AJ41)^(1/3)-1)*100,"") | V2: =IFERROR((('Raw Data 3Y'!AM41/'Raw Data 3Y'!AL41)^(1/3)-1)*100,"") | W2: =IFERROR((('Raw Data 3Y'!AO41/'Raw Data 3Y'!AN41)^(1/3)-1)*100,"") | X2: =IF(AND(ISNUMBER(F2),COUNT(F$2:F$46)>=4),IF(F2>=QUARTILE(F$2:F$46,3),1,0),0)+IF(AND(ISNUMBER(G2),COUNT(G$2:G$46)>=4),IF(G2>=QUARTILE(G$2:G$46,3),1,0),0)+IF(AND(ISNUMBER(H2),COUNT(H$2:H$46)>=4),IF(H2>=QUARTILE(H$2:H$46,3),1,0),0)+IF(AND(ISNUMBER(I2),COUNT(I$2:I$46)>=4),IF(I2>=QUARTILE(I$2:I$46,3),1,0),0)+IF(AND(ISNUMBER(J2),COUNT(J$2:J$46)>=4),IF(J2>=QUARTILE(J$2:J$46,3),1,0),0)+IF(AND(ISNUMBER(K2),COUNT(K$2:K$46)>=4),IF(K2>=QUARTILE(K$2:K$46,3),1,0),0)+IF(AND(ISNUMBER(L2),COUNT(L$2:L$46)>=4),IF(L2>=QUARTILE(L$2:L$46,3),1,0),0)+IF(AND(ISNUMBER(M2),COUNT(M$2:M$46)>=4),IF(M2>=QUARTILE(M$2:M$46,3),1,0),0)+IF(AND(ISNUMBER(N2),COUNT(N$2:N$46)>=4),IF(N2>=QUARTILE(N$2:N$46,3),1,0),0)+IF(AND(ISNUMBER(O2),COUNT(O$2:O$46)>=4),IF(O2>=QUARTILE(O$2:O$46,3),1,0),0)+IF(AND(ISNUMBER(P2),COUNT(P$2:P$46)>=4),IF(P2>=QUARTILE(P$2:P$46,3),1,0),0)+IF(AND(ISNUMBER(Q2),COUNT(Q$2:Q$46)>=4),IF(Q2>=QUARTILE(Q$2:Q$46,3),1,0),0)+IF(AND(ISNUMBER(R2),COUNT(R$2:R$46)>=4),IF(R2>=QUARTILE(R$2:R$46,3),1,0),0)+IF(AND(ISNUMBER(S2),COUNT(S$2:S$46)>=4),IF(S2>=QUARTILE(S$2:S$46,3),1,0),0)+IF(AND(ISNUMBER(T2),COUNT(T$2:T$46)>=4),IF(T2>=QUARTILE(T$2:T$46,3),1,0),0)+IF(AND(ISNUMBER(U2),COUNT(U$2:U$46)>=4),IF(U2>=QUARTILE(U$2:U$46,3),1,0),0)+IF(AND(ISNUMBER(V2),COUNT(V$2:V$46)>=4),IF(V2>=QUARTILE(V$2:V$46,3),1,0),0)+IF(AND(ISNUMBER(W2),COUNT(W$2:W$46)>=4),IF(W2>=QUARTILE(W$2:W$46,3),1,0),0) | Y2: =IF(AND(ISNUMBER(F2),COUNT(F$2:F$46)>=4),IF(F2<=QUARTILE(F$2:F$46,1),1,0),0)+IF(AND(ISNUMBER(G2),COUNT(G$2:G$46)>=4),IF(G2<=QUARTILE(G$2:G$46,1),1,0),0)+IF(AND(ISNUMBER(H2),COUNT(H$2:H$46)>=4),IF(H2<=QUARTILE(H$2:H$46,1),1,0),0)+IF(AND(ISNUMBER(I2),COUNT(I$2:I$46)>=4),IF(I2<=QUARTILE(I$2:I$46,1),1,0),0)+IF(AND(ISNUMBER(J2),COUNT(J$2:J$46)>=4),IF(J2<=QUARTILE(J$2:J$46,1),1,0),0)+IF(AND(ISNUMBER(K2),COUNT(K$2:K$46)>=4),IF(K2<=QUARTILE(K$2:K$46,1),1,0),0)+IF(AND(ISNUMBER(L2),COUNT(L$2:L$46)>=4),IF(L2<=QUARTILE(L$2:L$46,1),1,0),0)+IF(AND(ISNUMBER(M2),COUNT(M$2:M$46)>=4),IF(M2<=QUARTILE(M$2:M$46,1),1,0),0)+IF(AND(ISNUMBER(N2),COUNT(N$2:N$46)>=4),IF(N2<=QUARTILE(N$2:N$46,1),1,0),0)+IF(AND(ISNUMBER(O2),COUNT(O$2:O$46)>=4),IF(O2<=QUARTILE(O$2:O$46,1),1,0),0)+IF(AND(ISNUMBER(P2),COUNT(P$2:P$46)>=4),IF(P2<=QUARTILE(P$2:P$46,1),1,0),0)+IF(AND(ISNUMBER(Q2),COUNT(Q$2:Q$46)>=4),IF(Q2<=QUARTILE(Q$2:Q$46,1),1,0),0)+IF(AND(ISNUMBER(R2),COUNT(R$2:R$46)>=4),IF(R2<=QUARTILE(R$2:R$46,1),1,0),0)+IF(AND(ISNUMBER(S2),COUNT(S$2:S$46)>=4),IF(S2<=QUARTILE(S$2:S$46,1),1,0),0)+IF(AND(ISNUMBER(T2),COUNT(T$2:T$46)>=4),IF(T2<=QUARTILE(T$2:T$46,1),1,0),0)+IF(AND(ISNUMBER(U2),COUNT(U$2:U$46)>=4),IF(U2<=QUARTILE(U$2:U$46,1),1,0),0)+IF(AND(ISNUMBER(V2),COUNT(V$2:V$46)>=4),IF(V2<=QUARTILE(V$2:V$46,1),1,0),0)+IF(AND(ISNUMBER(W2),COUNT(W$2:W$46)>=4),IF(W2<=QUARTILE(W$2:W$46,1),1,0),0) | Z2: =IF(Y2=0,X2,ROUND(X2/Y2,2)) | AA2: =IFERROR(IF(VLOOKUP(A2,'Raw Data 3Y'!A:AP,42,FALSE)="","none",VLOOKUP(A2,'Raw Data 3Y'!A:AP,42,FALSE)),"none") | AB2: Source
A3: ='Raw Data 3Y'!A39 | B3: =IFERROR((('Raw Data 3Y'!C39/'Raw Data 3Y'!B39)^(1/'Raw Data 3Y'!D39)-1)*100,"") | C3: ='Raw Data 3Y'!E39 | D3: =INT('Raw Data 3Y'!D39) | E3: =IFERROR(AVERAGE(F3:W3),"") | F3: =IFERROR((('Raw Data 3Y'!G39/'Raw Data 3Y'!F39)^(1/3)-1)*100,"") | G3: =IFERROR((('Raw Data 3Y'!I39/'Raw Data 3Y'!H39)^(1/3)-1)*100,"") | H3: =IFERROR((('Raw Data 3Y'!K39/'Raw Data 3Y'!J39)^(1/3)-1)*100,"") | I3: =IFERROR((('Raw Data 3Y'!M39/'Raw Data 3Y'!L39)^(1/3)-1)*100,"") | J3: =IFERROR((('Raw Data 3Y'!O39/'Raw Data 3Y'!N39)^(1/3)-1)*100,"") | K3: =IFERROR((('Raw Data 3Y'!Q39/'Raw Data 3Y'!P39)^(1/3)-1)*100,"") | L3: =IFERROR((('Raw Data 3Y'!S39/'Raw Data 3Y'!R39)^(1/3)-1)*100,"") | M3: =IFERROR((('Raw Data 3Y'!U39/'Raw Data 3Y'!T39)^(1/3)-1)*100,"") | N3: =IFERROR((('Raw Data 3Y'!W39/'Raw Data 3Y'!V39)^(1/3)-1)*100,"") | O3: =IFERROR((('Raw Data 3Y'!Y39/'Raw Data 3Y'!X39)^(1/3)-1)*100,"") | P3: =IFERROR((('Raw Data 3Y'!AA39/'Raw Data 3Y'!Z39)^(1/3)-1)*100,"") | Q3: =IFERROR((('Raw Data 3Y'!AC39/'Raw Data 3Y'!AB39)^(1/3)-1)*100,"") | R3: =IFERROR((('Raw Data 3Y'!AE39/'Raw Data 3Y'!AD39)^(1/3)-1)*100,"") | S3: =IFERROR((('Raw Data 3Y'!AG39/'Raw Data 3Y'!AF39)^(1/3)-1)*100,"") | T3: =IFERROR((('Raw Data 3Y'!AI39/'Raw Data 3Y'!AH39)^(1/3)-1)*100,"") | U3: =IFERROR((('Raw Data 3Y'!AK39/'Raw Data 3Y'!AJ39)^(1/3)-1)*100,"") | V3: =IFERROR((('Raw Data 3Y'!AM39/'Raw Data 3Y'!AL39)^(1/3)-1)*100,"") | W3: =IFERROR((('Raw Data 3Y'!AO39/'Raw Data 3Y'!AN39)^(1/3)-1)*100,"") | X3: =IF(AND(ISNUMBER(F3),COUNT(F$2:F$46)>=4),IF(F3>=QUARTILE(F$2:F$46,3),1,0),0)+IF(AND(ISNUMBER(G3),COUNT(G$2:G$46)>=4),IF(G3>=QUARTILE(G$2:G$46,3),1,0),0)+IF(AND(ISNUMBER(H3),COUNT(H$2:H$46)>=4),IF(H3>=QUARTILE(H$2:H$46,3),1,0),0)+IF(AND(ISNUMBER(I3),COUNT(I$2:I$46)>=4),IF(I3>=QUARTILE(I$2:I$46,3),1,0),0)+IF(AND(ISNUMBER(J3),COUNT(J$2:J$46)>=4),IF(J3>=QUARTILE(J$2:J$46,3),1,0),0)+IF(AND(ISNUMBER(K3),COUNT(K$2:K$46)>=4),IF(K3>=QUARTILE(K$2:K$46,3),1,0),0)+IF(AND(ISNUMBER(L3),COUNT(L$2:L$46)>=4),IF(L3>=QUARTILE(L$2:L$46,3),1,0),0)+IF(AND(ISNUMBER(M3),COUNT(M$2:M$46)>=4),IF(M3>=QUARTILE(M$2:M$46,3),1,0),0)+IF(AND(ISNUMBER(N3),COUNT(N$2:N$46)>=4),IF(N3>=QUARTILE(N$2:N$46,3),1,0),0)+IF(AND(ISNUMBER(O3),COUNT(O$2:O$46)>=4),IF(O3>=QUARTILE(O$2:O$46,3),1,0),0)+IF(AND(ISNUMBER(P3),COUNT(P$2:P$46)>=4),IF(P3>=QUARTILE(P$2:P$46,3),1,0),0)+IF(AND(ISNUMBER(Q3),COUNT(Q$2:Q$46)>=4),IF(Q3>=QUARTILE(Q$2:Q$46,3),1,0),0)+IF(AND(ISNUMBER(R3),COUNT(R$2:R$46)>=4),IF(R3>=QUARTILE(R$2:R$46,3),1,0),0)+IF(AND(ISNUMBER(S3),COUNT(S$2:S$46)>=4),IF(S3>=QUARTILE(S$2:S$46,3),1,0),0)+IF(AND(ISNUMBER(T3),COUNT(T$2:T$46)>=4),IF(T3>=QUARTILE(T$2:T$46,3),1,0),0)+IF(AND(ISNUMBER(U3),COUNT(U$2:U$46)>=4),IF(U3>=QUARTILE(U$2:U$46,3),1,0),0)+IF(AND(ISNUMBER(V3),COUNT(V$2:V$46)>=4),IF(V3>=QUARTILE(V$2:V$46,3),1,0),0)+IF(AND(ISNUMBER(W3),COUNT(W$2:W$46)>=4),IF(W3>=QUARTILE(W$2:W$46,3),1,0),0) | Y3: =IF(AND(ISNUMBER(F3),COUNT(F$2:F$46)>=4),IF(F3<=QUARTILE(F$2:F$46,1),1,0),0)+IF(AND(ISNUMBER(G3),COUNT(G$2:G$46)>=4),IF(G3<=QUARTILE(G$2:G$46,1),1,0),0)+IF(AND(ISNUMBER(H3),COUNT(H$2:H$46)>=4),IF(H3<=QUARTILE(H$2:H$46,1),1,0),0)+IF(AND(ISNUMBER(I3),COUNT(I$2:I$46)>=4),IF(I3<=QUARTILE(I$2:I$46,1),1,0),0)+IF(AND(ISNUMBER(J3),COUNT(J$2:J$46)>=4),IF(J3<=QUARTILE(J$2:J$46,1),1,0),0)+IF(AND(ISNUMBER(K3),COUNT(K$2:K$46)>=4),IF(K3<=QUARTILE(K$2:K$46,1),1,0),0)+IF(AND(ISNUMBER(L3),COUNT(L$2:L$46)>=4),IF(L3<=QUARTILE(L$2:L$46,1),1,0),0)+IF(AND(ISNUMBER(M3),COUNT(M$2:M$46)>=4),IF(M3<=QUARTILE(M$2:M$46,1),1,0),0)+IF(AND(ISNUMBER(N3),COUNT(N$2:N$46)>=4),IF(N3<=QUARTILE(N$2:N$46,1),1,0),0)+IF(AND(ISNUMBER(O3),COUNT(O$2:O$46)>=4),IF(O3<=QUARTILE(O$2:O$46,1),1,0),0)+IF(AND(ISNUMBER(P3),COUNT(P$2:P$46)>=4),IF(P3<=QUARTILE(P$2:P$46,1),1,0),0)+IF(AND(ISNUMBER(Q3),COUNT(Q$2:Q$46)>=4),IF(Q3<=QUARTILE(Q$2:Q$46,1),1,0),0)+IF(AND(ISNUMBER(R3),COUNT(R$2:R$46)>=4),IF(R3<=QUARTILE(R$2:R$46,1),1,0),0)+IF(AND(ISNUMBER(S3),COUNT(S$2:S$46)>=4),IF(S3<=QUARTILE(S$2:S$46,1),1,0),0)+IF(AND(ISNUMBER(T3),COUNT(T$2:T$46)>=4),IF(T3<=QUARTILE(T$2:T$46,1),1,0),0)+IF(AND(ISNUMBER(U3),COUNT(U$2:U$46)>=4),IF(U3<=QUARTILE(U$2:U$46,1),1,0),0)+IF(AND(ISNUMBER(V3),COUNT(V$2:V$46)>=4),IF(V3<=QUARTILE(V$2:V$46,1),1,0),0)+IF(AND(ISNUMBER(W3),COUNT(W$2:W$46)>=4),IF(W3<=QUARTILE(W$2:W$46,1),1,0),0) | Z3: =IF(Y3=0,X3,ROUND(X3/Y3,2)) | AA3: =IFERROR(IF(VLOOKUP(A3,'Raw Data 3Y'!A:AP,42,FALSE)="","none",VLOOKUP(A3,'Raw Data 3Y'!A:AP,42,FALSE)),"none") | AB3: Source
A4: ='Raw Data 3Y'!A21 | B4: =IFERROR((('Raw Data 3Y'!C21/'Raw Data 3Y'!B21)^(1/'Raw Data 3Y'!D21)-1)*100,"") | C4: ='Raw Data 3Y'!E21 | D4: =INT('Raw Data 3Y'!D21) | E4: =IFERROR(AVERAGE(F4:W4),"") | F4: =IFERROR((('Raw Data 3Y'!G21/'Raw Data 3Y'!F21)^(1/3)-1)*100,"") | G4: =IFERROR((('Raw Data 3Y'!I21/'Raw Data 3Y'!H21)^(1/3)-1)*100,"") | H4: =IFERROR((('Raw Data 3Y'!K21/'Raw Data 3Y'!J21)^(1/3)-1)*100,"") | I4: =IFERROR((('Raw Data 3Y'!M21/'Raw Data 3Y'!L21)^(1/3)-1)*100,"") | J4: =IFERROR((('Raw Data 3Y'!O21/'Raw Data 3Y'!N21)^(1/3)-1)*100,"") | K4: =IFERROR((('Raw Data 3Y'!Q21/'Raw Data 3Y'!P21)^(1/3)-1)*100,"") | L4: =IFERROR((('Raw Data 3Y'!S21/'Raw Data 3Y'!R21)^(1/3)-1)*100,"") | M4: =IFERROR((('Raw Data 3Y'!U21/'Raw Data 3Y'!T21)^(1/3)-1)*100,"") | N4: =IFERROR((('Raw Data 3Y'!W21/'Raw Data 3Y'!V21)^(1/3)-1)*100,"") | O4: =IFERROR((('Raw Data 3Y'!Y21/'Raw Data 3Y'!X21)^(1/3)-1)*100,"") | P4: =IFERROR((('Raw Data 3Y'!AA21/'Raw Data 3Y'!Z21)^(1/3)-1)*100,"") | Q4: =IFERROR((('Raw Data 3Y'!AC21/'Raw Data 3Y'!AB21)^(1/3)-1)*100,"") | R4: =IFERROR((('Raw Data 3Y'!AE21/'Raw Data 3Y'!AD21)^(1/3)-1)*100,"") | S4: =IFERROR((('Raw Data 3Y'!AG21/'Raw Data 3Y'!AF21)^(1/3)-1)*100,"") | T4: =IFERROR((('Raw Data 3Y'!AI21/'Raw Data 3Y'!AH21)^(1/3)-1)*100,"") | U4: =IFERROR((('Raw Data 3Y'!AK21/'Raw Data 3Y'!AJ21)^(1/3)-1)*100,"") | V4: =IFERROR((('Raw Data 3Y'!AM21/'Raw Data 3Y'!AL21)^(1/3)-1)*100,"") | W4: =IFERROR((('Raw Data 3Y'!AO21/'Raw Data 3Y'!AN21)^(1/3)-1)*100,"") | X4: =IF(AND(ISNUMBER(F4),COUNT(F$2:F$46)>=4),IF(F4>=QUARTILE(F$2:F$46,3),1,0),0)+IF(AND(ISNUMBER(G4),COUNT(G$2:G$46)>=4),IF(G4>=QUARTILE(G$2:G$46,3),1,0),0)+IF(AND(ISNUMBER(H4),COUNT(H$2:H$46)>=4),IF(H4>=QUARTILE(H$2:H$46,3),1,0),0)+IF(AND(ISNUMBER(I4),COUNT(I$2:I$46)>=4),IF(I4>=QUARTILE(I$2:I$46,3),1,0),0)+IF(AND(ISNUMBER(J4),COUNT(J$2:J$46)>=4),IF(J4>=QUARTILE(J$2:J$46,3),1,0),0)+IF(AND(ISNUMBER(K4),COUNT(K$2:K$46)>=4),IF(K4>=QUARTILE(K$2:K$46,3),1,0),0)+IF(AND(ISNUMBER(L4),COUNT(L$2:L$46)>=4),IF(L4>=QUARTILE(L$2:L$46,3),1,0),0)+IF(AND(ISNUMBER(M4),COUNT(M$2:M$46)>=4),IF(M4>=QUARTILE(M$2:M$46,3),1,0),0)+IF(AND(ISNUMBER(N4),COUNT(N$2:N$46)>=4),IF(N4>=QUARTILE(N$2:N$46,3),1,0),0)+IF(AND(ISNUMBER(O4),COUNT(O$2:O$46)>=4),IF(O4>=QUARTILE(O$2:O$46,3),1,0),0)+IF(AND(ISNUMBER(P4),COUNT(P$2:P$46)>=4),IF(P4>=QUARTILE(P$2:P$46,3),1,0),0)+IF(AND(ISNUMBER(Q4),COUNT(Q$2:Q$46)>=4),IF(Q4>=QUARTILE(Q$2:Q$46,3),1,0),0)+IF(AND(ISNUMBER(R4),COUNT(R$2:R$46)>=4),IF(R4>=QUARTILE(R$2:R$46,3),1,0),0)+IF(AND(ISNUMBER(S4),COUNT(S$2:S$46)>=4),IF(S4>=QUARTILE(S$2:S$46,3),1,0),0)+IF(AND(ISNUMBER(T4),COUNT(T$2:T$46)>=4),IF(T4>=QUARTILE(T$2:T$46,3),1,0),0)+IF(AND(ISNUMBER(U4),COUNT(U$2:U$46)>=4),IF(U4>=QUARTILE(U$2:U$46,3),1,0),0)+IF(AND(ISNUMBER(V4),COUNT(V$2:V$46)>=4),IF(V4>=QUARTILE(V$2:V$46,3),1,0),0)+IF(AND(ISNUMBER(W4),COUNT(W$2:W$46)>=4),IF(W4>=QUARTILE(W$2:W$46,3),1,0),0) | Y4: =IF(AND(ISNUMBER(F4),COUNT(F$2:F$46)>=4),IF(F4<=QUARTILE(F$2:F$46,1),1,0),0)+IF(AND(ISNUMBER(G4),COUNT(G$2:G$46)>=4),IF(G4<=QUARTILE(G$2:G$46,1),1,0),0)+IF(AND(ISNUMBER(H4),COUNT(H$2:H$46)>=4),IF(H4<=QUARTILE(H$2:H$46,1),1,0),0)+IF(AND(ISNUMBER(I4),COUNT(I$2:I$46)>=4),IF(I4<=QUARTILE(I$2:I$46,1),1,0),0)+IF(AND(ISNUMBER(J4),COUNT(J$2:J$46)>=4),IF(J4<=QUARTILE(J$2:J$46,1),1,0),0)+IF(AND(ISNUMBER(K4),COUNT(K$2:K$46)>=4),IF(K4<=QUARTILE(K$2:K$46,1),1,0),0)+IF(AND(ISNUMBER(L4),COUNT(L$2:L$46)>=4),IF(L4<=QUARTILE(L$2:L$46,1),1,0),0)+IF(AND(ISNUMBER(M4),COUNT(M$2:M$46)>=4),IF(M4<=QUARTILE(M$2:M$46,1),1,0),0)+IF(AND(ISNUMBER(N4),COUNT(N$2:N$46)>=4),IF(N4<=QUARTILE(N$2:N$46,1),1,0),0)+IF(AND(ISNUMBER(O4),COUNT(O$2:O$46)>=4),IF(O4<=QUARTILE(O$2:O$46,1),1,0),0)+IF(AND(ISNUMBER(P4),COUNT(P$2:P$46)>=4),IF(P4<=QUARTILE(P$2:P$46,1),1,0),0)+IF(AND(ISNUMBER(Q4),COUNT(Q$2:Q$46)>=4),IF(Q4<=QUARTILE(Q$2:Q$46,1),1,0),0)+IF(AND(ISNUMBER(R4),COUNT(R$2:R$46)>=4),IF(R4<=QUARTILE(R$2:R$46,1),1,0),0)+IF(AND(ISNUMBER(S4),COUNT(S$2:S$46)>=4),IF(S4<=QUARTILE(S$2:S$46,1),1,0),0)+IF(AND(ISNUMBER(T4),COUNT(T$2:T$46)>=4),IF(T4<=QUARTILE(T$2:T$46,1),1,0),0)+IF(AND(ISNUMBER(U4),COUNT(U$2:U$46)>=4),IF(U4<=QUARTILE(U$2:U$46,1),1,0),0)+IF(AND(ISNUMBER(V4),COUNT(V$2:V$46)>=4),IF(V4<=QUARTILE(V$2:V$46,1),1,0),0)+IF(AND(ISNUMBER(W4),COUNT(W$2:W$46)>=4),IF(W4<=QUARTILE(W$2:W$46,1),1,0),0) | Z4: =IF(Y4=0,X4,ROUND(X4/Y4,2)) | AA4: =IFERROR(IF(VLOOKUP(A4,'Raw Data 3Y'!A:AP,42,FALSE)="","none",VLOOKUP(A4,'Raw Data 3Y'!A:AP,42,FALSE)),"none") | AB4: Source
A5: ='Raw Data 3Y'!A23 | B5: =IFERROR((('Raw Data 3Y'!C23/'Raw Data 3Y'!B23)^(1/'Raw Data 3Y'!D23)-1)*100,"") | C5: ='Raw Data 3Y'!E23 | D5: =INT('Raw Data 3Y'!D23) | E5: =IFERROR(AVERAGE(F5:W5),"") | F5: =IFERROR((('Raw Data 3Y'!G23/'Raw Data 3Y'!F23)^(1/3)-1)*100,"") | G5: =IFERROR((('Raw Data 3Y'!I23/'Raw Data 3Y'!H23)^(1/3)-1)*100,"") | H5: =IFERROR((('Raw Data 3Y'!K23/'Raw Data 3Y'!J23)^(1/3)-1)*100,"") | I5: =IFERROR((('Raw Data 3Y'!M23/'Raw Data 3Y'!L23)^(1/3)-1)*100,"") | J5: =IFERROR((('Raw Data 3Y'!O23/'Raw Data 3Y'!N23)^(1/3)-1)*100,"") | K5: =IFERROR((('Raw Data 3Y'!Q23/'Raw Data 3Y'!P23)^(1/3)-1)*100,"") | L5: =IFERROR((('Raw Data 3Y'!S23/'Raw Data 3Y'!R23)^(1/3)-1)*100,"") | M5: =IFERROR((('Raw Data 3Y'!U23/'Raw Data 3Y'!T23)^(1/3)-1)*100,"") | N5: =IFERROR((('Raw Data 3Y'!W23/'Raw Data 3Y'!V23)^(1/3)-1)*100,"") | O5: =IFERROR((('Raw Data 3Y'!Y23/'Raw Data 3Y'!X23)^(1/3)-1)*100,"") | P5: =IFERROR((('Raw Data 3Y'!AA23/'Raw Data 3Y'!Z23)^(1/3)-1)*100,"") | Q5: =IFERROR((('Raw Data 3Y'!AC23/'Raw Data 3Y'!AB23)^(1/3)-1)*100,"") | R5: =IFERROR((('Raw Data 3Y'!AE23/'Raw Data 3Y'!AD23)^(1/3)-1)*100,"") | S5: =IFERROR((('Raw Data 3Y'!AG23/'Raw Data 3Y'!AF23)^(1/3)-1)*100,"") | T5: =IFERROR((('Raw Data 3Y'!AI23/'Raw Data 3Y'!AH23)^(1/3)-1)*100,"") | U5: =IFERROR((('Raw Data 3Y'!AK23/'Raw Data 3Y'!AJ23)^(1/3)-1)*100,"") | V5: =IFERROR((('Raw Data 3Y'!AM23/'Raw Data 3Y'!AL23)^(1/3)-1)*100,"") | W5: =IFERROR((('Raw Data 3Y'!AO23/'Raw Data 3Y'!AN23)^(1/3)-1)*100,"") | X5: =IF(AND(ISNUMBER(F5),COUNT(F$2:F$46)>=4),IF(F5>=QUARTILE(F$2:F$46,3),1,0),0)+IF(AND(ISNUMBER(G5),COUNT(G$2:G$46)>=4),IF(G5>=QUARTILE(G$2:G$46,3),1,0),0)+IF(AND(ISNUMBER(H5),COUNT(H$2:H$46)>=4),IF(H5>=QUARTILE(H$2:H$46,3),1,0),0)+IF(AND(ISNUMBER(I5),COUNT(I$2:I$46)>=4),IF(I5>=QUARTILE(I$2:I$46,3),1,0),0)+IF(AND(ISNUMBER(J5),COUNT(J$2:J$46)>=4),IF(J5>=QUARTILE(J$2:J$46,3),1,0),0)+IF(AND(ISNUMBER(K5),COUNT(K$2:K$46)>=4),IF(K5>=QUARTILE(K$2:K$46,3),1,0),0)+IF(AND(ISNUMBER(L5),COUNT(L$2:L$46)>=4),IF(L5>=QUARTILE(L$2:L$46,3),1,0),0)+IF(AND(ISNUMBER(M5),COUNT(M$2:M$46)>=4),IF(M5>=QUARTILE(M$2:M$46,3),1,0),0)+IF(AND(ISNUMBER(N5),COUNT(N$2:N$46)>=4),IF(N5>=QUARTILE(N$2:N$46,3),1,0),0)+IF(AND(ISNUMBER(O5),COUNT(O$2:O$46)>=4),IF(O5>=QUARTILE(O$2:O$46,3),1,0),0)+IF(AND(ISNUMBER(P5),COUNT(P$2:P$46)>=4),IF(P5>=QUARTILE(P$2:P$46,3),1,0),0)+IF(AND(ISNUMBER(Q5),COUNT(Q$2:Q$46)>=4),IF(Q5>=QUARTILE(Q$2:Q$46,3),1,0),0)+IF(AND(ISNUMBER(R5),COUNT(R$2:R$46)>=4),IF(R5>=QUARTILE(R$2:R$46,3),1,0),0)+IF(AND(ISNUMBER(S5),COUNT(S$2:S$46)>=4),IF(S5>=QUARTILE(S$2:S$46,3),1,0),0)+IF(AND(ISNUMBER(T5),COUNT(T$2:T$46)>=4),IF(T5>=QUARTILE(T$2:T$46,3),1,0),0)+IF(AND(ISNUMBER(U5),COUNT(U$2:U$46)>=4),IF(U5>=QUARTILE(U$2:U$46,3),1,0),0)+IF(AND(ISNUMBER(V5),COUNT(V$2:V$46)>=4),IF(V5>=QUARTILE(V$2:V$46,3),1,0),0)+IF(AND(ISNUMBER(W5),COUNT(W$2:W$46)>=4),IF(W5>=QUARTILE(W$2:W$46,3),1,0),0) | Y5: =IF(AND(ISNUMBER(F5),COUNT(F$2:F$46)>=4),IF(F5<=QUARTILE(F$2:F$46,1),1,0),0)+IF(AND(ISNUMBER(G5),COUNT(G$2:G$46)>=4),IF(G5<=QUARTILE(G$2:G$46,1),1,0),0)+IF(AND(ISNUMBER(H5),COUNT(H$2:H$46)>=4),IF(H5<=QUARTILE(H$2:H$46,1),1,0),0)+IF(AND(ISNUMBER(I5),COUNT(I$2:I$46)>=4),IF(I5<=QUARTILE(I$2:I$46,1),1,0),0)+IF(AND(ISNUMBER(J5),COUNT(J$2:J$46)>=4),IF(J5<=QUARTILE(J$2:J$46,1),1,0),0)+IF(AND(ISNUMBER(K5),COUNT(K$2:K$46)>=4),IF(K5<=QUARTILE(K$2:K$46,1),1,0),0)+IF(AND(ISNUMBER(L5),COUNT(L$2:L$46)>=4),IF(L5<=QUARTILE(L$2:L$46,1),1,0),0)+IF(AND(ISNUMBER(M5),COUNT(M$2:M$46)>=4),IF(M5<=QUARTILE(M$2:M$46,1),1,0),0)+IF(AND(ISNUMBER(N5),COUNT(N$2:N$46)>=4),IF(N5<=QUARTILE(N$2:N$46,1),1,0),0)+IF(AND(ISNUMBER(O5),COUNT(O$2:O$46)>=4),IF(O5<=QUARTILE(O$2:O$46,1),1,0),0)+IF(AND(ISNUMBER(P5),COUNT(P$2:P$46)>=4),IF(P5<=QUARTILE(P$2:P$46,1),1,0),0)+IF(AND(ISNUMBER(Q5),COUNT(Q$2:Q$46)>=4),IF(Q5<=QUARTILE(Q$2:Q$46,1),1,0),0)+IF(AND(ISNUMBER(R5),COUNT(R$2:R$46)>=4),IF(R5<=QUARTILE(R$2:R$46,1),1,0),0)+IF(AND(ISNUMBER(S5),COUNT(S$2:S$46)>=4),IF(S5<=QUARTILE(S$2:S$46,1),1,0),0)+IF(AND(ISNUMBER(T5),COUNT(T$2:T$46)>=4),IF(T5<=QUARTILE(T$2:T$46,1),1,0),0)+IF(AND(ISNUMBER(U5),COUNT(U$2:U$46)>=4),IF(U5<=QUARTILE(U$2:U$46,1),1,0),0)+IF(AND(ISNUMBER(V5),COUNT(V$2:V$46)>=4),IF(V5<=QUARTILE(V$2:V$46,1),1,0),0)+IF(AND(ISNUMBER(W5),COUNT(W$2:W$46)>=4),IF(W5<=QUARTILE(W$2:W$46,1),1,0),0) | Z5: =IF(Y5=0,X5,ROUND(X5/Y5,2)) | AA5: =IFERROR(IF(VLOOKUP(A5,'Raw Data 3Y'!A:AP,42,FALSE)="","none",VLOOKUP(A5,'Raw Data 3Y'!A:AP,42,FALSE)),"none") | AB5: Source
A6: ='Raw Data 3Y'!A16 | B6: =IFERROR((('Raw Data 3Y'!C16/'Raw Data 3Y'!B16)^(1/'Raw Data 3Y'!D16)-1)*100,"") | C6: ='Raw Data 3Y'!E16 | D6: =INT('Raw Data 3Y'!D16) | E6: =IFERROR(AVERAGE(F6:W6),"") | F6: =IFERROR((('Raw Data 3Y'!G16/'Raw Data 3Y'!F16)^(1/3)-1)*100,"") | G6: =IFERROR((('Raw Data 3Y'!I16/'Raw Data 3Y'!H16)^(1/3)-1)*100,"") | H6: =IFERROR((('Raw Data 3Y'!K16/'Raw Data 3Y'!J16)^(1/3)-1)*100,"") | I6: =IFERROR((('Raw Data 3Y'!M16/'Raw Data 3Y'!L16)^(1/3)-1)*100,"") | J6: =IFERROR((('Raw Data 3Y'!O16/'Raw Data 3Y'!N16)^(1/3)-1)*100,"") | K6: =IFERROR((('Raw Data 3Y'!Q16/'Raw Data 3Y'!P16)^(1/3)-1)*100,"") | L6: =IFERROR((('Raw Data 3Y'!S16/'Raw Data 3Y'!R16)^(1/3)-1)*100,"") | M6: =IFERROR((('Raw Data 3Y'!U16/'Raw Data 3Y'!T16)^(1/3)-1)*100,"") | N6: =IFERROR((('Raw Data 3Y'!W16/'Raw Data 3Y'!V16)^(1/3)-1)*100,"") | O6: =IFERROR((('Raw Data 3Y'!Y16/'Raw Data 3Y'!X16)^(1/3)-1)*100,"") | P6: =IFERROR((('Raw Data 3Y'!AA16/'Raw Data 3Y'!Z16)^(1/3)-1)*100,"") | Q6: =IFERROR((('Raw Data 3Y'!AC16/'Raw Data 3Y'!AB16)^(1/3)-1)*100,"") | R6: =IFERROR((('Raw Data 3Y'!AE16/'Raw Data 3Y'!AD16)^(1/3)-1)*100,"") | S6: =IFERROR((('Raw Data 3Y'!AG16/'Raw Data 3Y'!AF16)^(1/3)-1)*100,"") | T6: =IFERROR((('Raw Data 3Y'!AI16/'Raw Data 3Y'!AH16)^(1/3)-1)*100,"") | U6: =IFERROR((('Raw Data 3Y'!AK16/'Raw Data 3Y'!AJ16)^(1/3)-1)*100,"") | V6: =IFERROR((('Raw Data 3Y'!AM16/'Raw Data 3Y'!AL16)^(1/3)-1)*100,"") | W6: =IFERROR((('Raw Data 3Y'!AO16/'Raw Data 3Y'!AN16)^(1/3)-1)*100,"") | X6: =IF(AND(ISNUMBER(F6),COUNT(F$2:F$46)>=4),IF(F6>=QUARTILE(F$2:F$46,3),1,0),0)+IF(AND(ISNUMBER(G6),COUNT(G$2:G$46)>=4),IF(G6>=QUARTILE(G$2:G$46,3),1,0),0)+IF(AND(ISNUMBER(H6),COUNT(H$2:H$46)>=4),IF(H6>=QUARTILE(H$2:H$46,3),1,0),0)+IF(AND(ISNUMBER(I6),COUNT(I$2:I$46)>=4),IF(I6>=QUARTILE(I$2:I$46,3),1,0),0)+IF(AND(ISNUMBER(J6),COUNT(J$2:J$46)>=4),IF(J6>=QUARTILE(J$2:J$46,3),1,0),0)+IF(AND(ISNUMBER(K6),COUNT(K$2:K$46)>=4),IF(K6>=QUARTILE(K$2:K$46,3),1,0),0)+IF(AND(ISNUMBER(L6),COUNT(L$2:L$46)>=4),IF(L6>=QUARTILE(L$2:L$46,3),1,0),0)+IF(AND(ISNUMBER(M6),COUNT(M$2:M$46)>=4),IF(M6>=QUARTILE(M$2:M$46,3),1,0),0)+IF(AND(ISNUMBER(N6),COUNT(N$2:N$46)>=4),IF(N6>=QUARTILE(N$2:N$46,3),1,0),0)+IF(AND(ISNUMBER(O6),COUNT(O$2:O$46)>=4),IF(O6>=QUARTILE(O$2:O$46,3),1,0),0)+IF(AND(ISNUMBER(P6),COUNT(P$2:P$46)>=4),IF(P6>=QUARTILE(P$2:P$46,3),1,0),0)+IF(AND(ISNUMBER(Q6),COUNT(Q$2:Q$46)>=4),IF(Q6>=QUARTILE(Q$2:Q$46,3),1,0),0)+IF(AND(ISNUMBER(R6),COUNT(R$2:R$46)>=4),IF(R6>=QUARTILE(R$2:R$46,3),1,0),0)+IF(AND(ISNUMBER(S6),COUNT(S$2:S$46)>=4),IF(S6>=QUARTILE(S$2:S$46,3),1,0),0)+IF(AND(ISNUMBER(T6),COUNT(T$2:T$46)>=4),IF(T6>=QUARTILE(T$2:T$46,3),1,0),0)+IF(AND(ISNUMBER(U6),COUNT(U$2:U$46)>=4),IF(U6>=QUARTILE(U$2:U$46,3),1,0),0)+IF(AND(ISNUMBER(V6),COUNT(V$2:V$46)>=4),IF(V6>=QUARTILE(V$2:V$46,3),1,0),0)+IF(AND(ISNUMBER(W6),COUNT(W$2:W$46)>=4),IF(W6>=QUARTILE(W$2:W$46,3),1,0),0) | Y6: =IF(AND(ISNUMBER(F6),COUNT(F$2:F$46)>=4),IF(F6<=QUARTILE(F$2:F$46,1),1,0),0)+IF(AND(ISNUMBER(G6),COUNT(G$2:G$46)>=4),IF(G6<=QUARTILE(G$2:G$46,1),1,0),0)+IF(AND(ISNUMBER(H6),COUNT(H$2:H$46)>=4),IF(H6<=QUARTILE(H$2:H$46,1),1,0),0)+IF(AND(ISNUMBER(I6),COUNT(I$2:I$46)>=4),IF(I6<=QUARTILE(I$2:I$46,1),1,0),0)+IF(AND(ISNUMBER(J6),COUNT(J$2:J$46)>=4),IF(J6<=QUARTILE(J$2:J$46,1),1,0),0)+IF(AND(ISNUMBER(K6),COUNT(K$2:K$46)>=4),IF(K6<=QUARTILE(K$2:K$46,1),1,0),0)+IF(AND(ISNUMBER(L6),COUNT(L$2:L$46)>=4),IF(L6<=QUARTILE(L$2:L$46,1),1,0),0)+IF(AND(ISNUMBER(M6),COUNT(M$2:M$46)>=4),IF(M6<=QUARTILE(M$2:M$46,1),1,0),0)+IF(AND(ISNUMBER(N6),COUNT(N$2:N$46)>=4),IF(N6<=QUARTILE(N$2:N$46,1),1,0),0)+IF(AND(ISNUMBER(O6),COUNT(O$2:O$46)>=4),IF(O6<=QUARTILE(O$2:O$46,1),1,0),0)+IF(AND(ISNUMBER(P6),COUNT(P$2:P$46)>=4),IF(P6<=QUARTILE(P$2:P$46,1),1,0),0)+IF(AND(ISNUMBER(Q6),COUNT(Q$2:Q$46)>=4),IF(Q6<=QUARTILE(Q$2:Q$46,1),1,0),0)+IF(AND(ISNUMBER(R6),COUNT(R$2:R$46)>=4),IF(R6<=QUARTILE(R$2:R$46,1),1,0),0)+IF(AND(ISNUMBER(S6),COUNT(S$2:S$46)>=4),IF(S6<=QUARTILE(S$2:S$46,1),1,0),0)+IF(AND(ISNUMBER(T6),COUNT(T$2:T$46)>=4),IF(T6<=QUARTILE(T$2:T$46,1),1,0),0)+IF(AND(ISNUMBER(U6),COUNT(U$2:U$46)>=4),IF(U6<=QUARTILE(U$2:U$46,1),1,0),0)+IF(AND(ISNUMBER(V6),COUNT(V$2:V$46)>=4),IF(V6<=QUARTILE(V$2:V$46,1),1,0),0)+IF(AND(ISNUMBER(W6),COUNT(W$2:W$46)>=4),IF(W6<=QUARTILE(W$2:W$46,1),1,0),0) | Z6: =IF(Y6=0,X6,ROUND(X6/Y6,2)) | AA6: =IFERROR(IF(VLOOKUP(A6,'Raw Data 3Y'!A:AP,42,FALSE)="","none",VLOOKUP(A6,'Raw Data 3Y'!A:AP,42,FALSE)),"none") | AB6: Source
A7: ='Raw Data 3Y'!A35 | B7: =IFERROR((('Raw Data 3Y'!C35/'Raw Data 3Y'!B35)^(1/'Raw Data 3Y'!D35)-1)*100,"") | C7: ='Raw Data 3Y'!E35 | D7: =INT('Raw Data 3Y'!D35) | E7: =IFERROR(AVERAGE(F7:W7),"") | F7: =IFERROR((('Raw Data 3Y'!G35/'Raw Data 3Y'!F35)^(1/3)-1)*100,"") | G7: =IFERROR((('Raw Data 3Y'!I35/'Raw Data 3Y'!H35)^(1/3)-1)*100,"") | H7: =IFERROR((('Raw Data 3Y'!K35/'Raw Data 3Y'!J35)^(1/3)-1)*100,"") | I7: =IFERROR((('Raw Data 3Y'!M35/'Raw Data 3Y'!L35)^(1/3)-1)*100,"") | J7: =IFERROR((('Raw Data 3Y'!O35/'Raw Data 3Y'!N35)^(1/3)-1)*100,"") | K7: =IFERROR((('Raw Data 3Y'!Q35/'Raw Data 3Y'!P35)^(1/3)-1)*100,"") | L7: =IFERROR((('Raw Data 3Y'!S35/'Raw Data 3Y'!R35)^(1/3)-1)*100,"") | M7: =IFERROR((('Raw Data 3Y'!U35/'Raw Data 3Y'!T35)^(1/3)-1)*100,"") | N7: =IFERROR((('Raw Data 3Y'!W35/'Raw Data 3Y'!V35)^(1/3)-1)*100,"") | O7: =IFERROR((('Raw Data 3Y'!Y35/'Raw Data 3Y'!X35)^(1/3)-1)*100,"") | P7: =IFERROR((('Raw Data 3Y'!AA35/'Raw Data 3Y'!Z35)^(1/3)-1)*100,"") | Q7: =IFERROR((('Raw Data 3Y'!AC35/'Raw Data 3Y'!AB35)^(1/3)-1)*100,"") | R7: =IFERROR((('Raw Data 3Y'!AE35/'Raw Data 3Y'!AD35)^(1/3)-1)*100,"") | S7: =IFERROR((('Raw Data 3Y'!AG35/'Raw Data 3Y'!AF35)^(1/3)-1)*100,"") | T7: =IFERROR((('Raw Data 3Y'!AI35/'Raw Data 3Y'!AH35)^(1/3)-1)*100,"") | U7: =IFERROR((('Raw Data 3Y'!AK35/'Raw Data 3Y'!AJ35)^(1/3)-1)*100,"") | V7: =IFERROR((('Raw Data 3Y'!AM35/'Raw Data 3Y'!AL35)^(1/3)-1)*100,"") | W7: =IFERROR((('Raw Data 3Y'!AO35/'Raw Data 3Y'!AN35)^(1/3)-1)*100,"") | X7: =IF(AND(ISNUMBER(F7),COUNT(F$2:F$46)>=4),IF(F7>=QUARTILE(F$2:F$46,3),1,0),0)+IF(AND(ISNUMBER(G7),COUNT(G$2:G$46)>=4),IF(G7>=QUARTILE(G$2:G$46,3),1,0),0)+IF(AND(ISNUMBER(H7),COUNT(H$2:H$46)>=4),IF(H7>=QUARTILE(H$2:H$46,3),1,0),0)+IF(AND(ISNUMBER(I7),COUNT(I$2:I$46)>=4),IF(I7>=QUARTILE(I$2:I$46,3),1,0),0)+IF(AND(ISNUMBER(J7),COUNT(J$2:J$46)>=4),IF(J7>=QUARTILE(J$2:J$46,3),1,0),0)+IF(AND(ISNUMBER(K7),COUNT(K$2:K$46)>=4),IF(K7>=QUARTILE(K$2:K$46,3),1,0),0)+IF(AND(ISNUMBER(L7),COUNT(L$2:L$46)>=4),IF(L7>=QUARTILE(L$2:L$46,3),1,0),0)+IF(AND(ISNUMBER(M7),COUNT(M$2:M$46)>=4),IF(M7>=QUARTILE(M$2:M$46,3),1,0),0)+IF(AND(ISNUMBER(N7),COUNT(N$2:N$46)>=4),IF(N7>=QUARTILE(N$2:N$46,3),1,0),0)+IF(AND(ISNUMBER(O7),COUNT(O$2:O$46)>=4),IF(O7>=QUARTILE(O$2:O$46,3),1,0),0)+IF(AND(ISNUMBER(P7),COUNT(P$2:P$46)>=4),IF(P7>=QUARTILE(P$2:P$46,3),1,0),0)+IF(AND(ISNUMBER(Q7),COUNT(Q$2:Q$46)>=4),IF(Q7>=QUARTILE(Q$2:Q$46,3),1,0),0)+IF(AND(ISNUMBER(R7),COUNT(R$2:R$46)>=4),IF(R7>=QUARTILE(R$2:R$46,3),1,0),0)+IF(AND(ISNUMBER(S7),COUNT(S$2:S$46)>=4),IF(S7>=QUARTILE(S$2:S$46,3),1,0),0)+IF(AND(ISNUMBER(T7),COUNT(T$2:T$46)>=4),IF(T7>=QUARTILE(T$2:T$46,3),1,0),0)+IF(AND(ISNUMBER(U7),COUNT(U$2:U$46)>=4),IF(U7>=QUARTILE(U$2:U$46,3),1,0),0)+IF(AND(ISNUMBER(V7),COUNT(V$2:V$46)>=4),IF(V7>=QUARTILE(V$2:V$46,3),1,0),0)+IF(AND(ISNUMBER(W7),COUNT(W$2:W$46)>=4),IF(W7>=QUARTILE(W$2:W$46,3),1,0),0) | Y7: =IF(AND(ISNUMBER(F7),COUNT(F$2:F$46)>=4),IF(F7<=QUARTILE(F$2:F$46,1),1,0),0)+IF(AND(ISNUMBER(G7),COUNT(G$2:G$46)>=4),IF(G7<=QUARTILE(G$2:G$46,1),1,0),0)+IF(AND(ISNUMBER(H7),COUNT(H$2:H$46)>=4),IF(H7<=QUARTILE(H$2:H$46,1),1,0),0)+IF(AND(ISNUMBER(I7),COUNT(I$2:I$46)>=4),IF(I7<=QUARTILE(I$2:I$46,1),1,0),0)+IF(AND(ISNUMBER(J7),COUNT(J$2:J$46)>=4),IF(J7<=QUARTILE(J$2:J$46,1),1,0),0)+IF(AND(ISNUMBER(K7),COUNT(K$2:K$46)>=4),IF(K7<=QUARTILE(K$2:K$46,1),1,0),0)+IF(AND(ISNUMBER(L7),COUNT(L$2:L$46)>=4),IF(L7<=QUARTILE(L$2:L$46,1),1,0),0)+IF(AND(ISNUMBER(M7),COUNT(M$2:M$46)>=4),IF(M7<=QUARTILE(M$2:M$46,1),1,0),0)+IF(AND(ISNUMBER(N7),COUNT(N$2:N$46)>=4),IF(N7<=QUARTILE(N$2:N$46,1),1,0),0)+IF(AND(ISNUMBER(O7),COUNT(O$2:O$46)>=4),IF(O7<=QUARTILE(O$2:O$46,1),1,0),0)+IF(AND(ISNUMBER(P7),COUNT(P$2:P$46)>=4),IF(P7<=QUARTILE(P$2:P$46,1),1,0),0)+IF(AND(ISNUMBER(Q7),COUNT(Q$2:Q$46)>=4),IF(Q7<=QUARTILE(Q$2:Q$46,1),1,0),0)+IF(AND(ISNUMBER(R7),COUNT(R$2:R$46)>=4),IF(R7<=QUARTILE(R$2:R$46,1),1,0),0)+IF(AND(ISNUMBER(S7),COUNT(S$2:S$46)>=4),IF(S7<=QUARTILE(S$2:S$46,1),1,0),0)+IF(AND(ISNUMBER(T7),COUNT(T$2:T$46)>=4),IF(T7<=QUARTILE(T$2:T$46,1),1,0),0)+IF(AND(ISNUMBER(U7),COUNT(U$2:U$46)>=4),IF(U7<=QUARTILE(U$2:U$46,1),1,0),0)+IF(AND(ISNUMBER(V7),COUNT(V$2:V$46)>=4),IF(V7<=QUARTILE(V$2:V$46,1),1,0),0)+IF(AND(ISNUMBER(W7),COUNT(W$2:W$46)>=4),IF(W7<=QUARTILE(W$2:W$46,1),1,0),0) | Z7: =IF(Y7=0,X7,ROUND(X7/Y7,2)) | AA7: =IFERROR(IF(VLOOKUP(A7,'Raw Data 3Y'!A:AP,42,FALSE)="","none",VLOOKUP(A7,'Raw Data 3Y'!A:AP,42,FALSE)),"none") | AB7: Source
